2019-02-16 13:19:09,737 - util.py[DEBUG]: Cloud-init v. 0.7.9 running 'init-local' at Sat, 16 Feb 2019 13:19:09 +0000. Up 6.20 seconds.
2019-02-16 13:19:09,738 - util.py[DEBUG]: Restoring selinux mode for /var/lib/cloud (recursive=False)
2019-02-16 13:19:09,738 - util.py[DEBUG]: Restoring selinux mode for /var/lib/cloud (recursive=True)
2019-02-16 13:19:09,739 - util.py[DEBUG]: Restoring selinux mode for /var/lib/cloud/scripts (recursive=False)
2019-02-16 13:19:09,740 - util.py[DEBUG]: Restoring selinux mode for /var/lib/cloud/scripts (recursive=True)
2019-02-16 13:19:09,740 - util.py[DEBUG]: Restoring selinux mode for /var/lib/cloud/scripts/per-instance (recursive=False)
2019-02-16 13:19:09,741 - util.py[DEBUG]: Restoring selinux mode for /var/lib/cloud/scripts (recursive=True)
2019-02-16 13:19:09,742 - util.py[DEBUG]: Restoring selinux mode for /var/lib/cloud/scripts/per-once (recursive=False)
2019-02-16 13:19:09,742 - util.py[DEBUG]: Restoring selinux mode for /var/lib/cloud/scripts (recursive=True)
2019-02-16 13:19:09,743 - util.py[DEBUG]: Restoring selinux mode for /var/lib/cloud/scripts/per-boot (recursive=False)
2019-02-16 13:19:09,743 - util.py[DEBUG]: Restoring selinux mode for /var/lib/cloud/scripts (recursive=True)
2019-02-16 13:19:09,744 - util.py[DEBUG]: Restoring selinux mode for /var/lib/cloud/scripts/vendor (recursive=False)
2019-02-16 13:19:09,745 - util.py[DEBUG]: Restoring selinux mode for /var/lib/cloud (recursive=True)
2019-02-16 13:19:09,747 - util.py[DEBUG]: Restoring selinux mode for /var/lib/cloud/seed (recursive=False)
2019-02-16 13:19:09,747 - util.py[DEBUG]: Restoring selinux mode for /var/lib/cloud (recursive=True)
2019-02-16 13:19:09,749 - util.py[DEBUG]: Restoring selinux mode for /var/lib/cloud/instances (recursive=False)
2019-02-16 13:19:09,749 - util.py[DEBUG]: Restoring selinux mode for /var/lib/cloud (recursive=True)
2019-02-16 13:19:09,751 - util.py[DEBUG]: Restoring selinux mode for /var/lib/cloud/handlers (recursive=False)
2019-02-16 13:19:09,751 - util.py[DEBUG]: Restoring selinux mode for /var/lib/cloud (recursive=True)
2019-02-16 13:19:09,753 - util.py[DEBUG]: Restoring selinux mode for /var/lib/cloud/sem (recursive=False)
2019-02-16 13:19:09,754 - util.py[DEBUG]: Restoring selinux mode for /var/lib/cloud/data (recursive=False)
2019-02-16 13:19:09,754 - util.py[DEBUG]: Writing to /var/log/cloud-init.log - ab: [384] 0 bytes
2019-02-16 13:19:09,755 - util.py[DEBUG]: Restoring selinux mode for /var/log/cloud-init.log (recursive=False)
2019-02-16 13:19:09,755 - util.py[DEBUG]: Restoring selinux mode for /var/log/cloud-init.log (recursive=False)
2019-02-16 13:19:09,756 - util.py[DEBUG]: Attempting to remove /var/lib/cloud/instance/boot-finished
2019-02-16 13:19:09,756 - util.py[DEBUG]: Attempting to remove /var/lib/cloud/data/no-net
2019-02-16 13:19:09,756 - handlers.py[DEBUG]: start: init-local/check-cache: attempting to read from cache [check]
2019-02-16 13:19:09,756 - util.py[DEBUG]: Reading from /var/lib/cloud/instance/obj.pkl (quiet=False)
2019-02-16 13:19:09,756 - stages.py[DEBUG]: no cache found
2019-02-16 13:19:09,756 - handlers.py[DEBUG]: finish: init-local/check-cache: SUCCESS: no cache found
2019-02-16 13:19:09,756 - util.py[DEBUG]: Attempting to remove /var/lib/cloud/instance
2019-02-16 13:19:09,770 - stages.py[DEBUG]: Using distro class <class 'cloudinit.distros.rhel.Distro'>
2019-02-16 13:19:09,770 - __init__.py[DEBUG]: Looking for for data source in: ['NoCloud', 'ConfigDrive', 'OpenNebula', 'DigitalOcean', 'Azure', 'AltCloud', 'OVF', 'MAAS', 'GCE', 'OpenStack', 'AliYun', 'Ec2', 'CloudSigma', 'CloudStack', 'SmartOS', 'Bigstep', 'None'], via packages ['', u'cloudinit.sources'] that matches dependencies ['FILESYSTEM']
2019-02-16 13:19:09,828 - __init__.py[DEBUG]: Searching for local data source in: [u'DataSourceNoCloud', u'DataSourceConfigDrive', u'DataSourceOpenNebula', u'DataSourceDigitalOcean', u'DataSourceOVF', u'DataSourceCloudSigma', u'DataSourceSmartOS']
2019-02-16 13:19:09,828 - handlers.py[DEBUG]: start: init-local/search-NoCloud: searching for local data from DataSourceNoCloud
2019-02-16 13:19:09,829 - __init__.py[DEBUG]: Seeing if we can get any data from <class 'cloudinit.sources.DataSourceNoCloud.DataSourceNoCloud'>
2019-02-16 13:19:09,829 - util.py[DEBUG]: Reading from /var/lib/cloud/seed/nocloud/user-data (quiet=False)
2019-02-16 13:19:09,829 - util.py[DEBUG]: Reading from /var/lib/cloud/seed/nocloud/meta-data (quiet=False)
2019-02-16 13:19:09,829 - util.py[DEBUG]: Reading from /var/lib/cloud/seed/nocloud/vendor-data (quiet=False)
2019-02-16 13:19:09,829 - util.py[DEBUG]: Reading from /var/lib/cloud/seed/nocloud/network-config (quiet=False)
2019-02-16 13:19:09,829 - util.py[DEBUG]: Reading from /var/lib/cloud/seed/nocloud-net/user-data (quiet=False)
2019-02-16 13:19:09,829 - util.py[DEBUG]: Reading from /var/lib/cloud/seed/nocloud-net/meta-data (quiet=False)
2019-02-16 13:19:09,829 - util.py[DEBUG]: Reading from /var/lib/cloud/seed/nocloud-net/vendor-data (quiet=False)
2019-02-16 13:19:09,830 - util.py[DEBUG]: Reading from /var/lib/cloud/seed/nocloud-net/network-config (quiet=False)
2019-02-16 13:19:09,830 - util.py[DEBUG]: Running command ['blkid', '-odevice', '/dev/sr0'] with allowed return codes [0, 2] (shell=False, capture=True)
2019-02-16 13:19:09,836 - util.py[DEBUG]: Running command ['blkid', '-odevice', '/dev/sr1'] with allowed return codes [0, 2] (shell=False, capture=True)
2019-02-16 13:19:09,839 - util.py[DEBUG]: Running command ['blkid', '-tTYPE=vfat', '-odevice'] with allowed return codes [0, 2] (shell=False, capture=True)
2019-02-16 13:19:09,853 - util.py[DEBUG]: Running command ['blkid', '-tTYPE=iso9660', '-odevice'] with allowed return codes [0, 2] (shell=False, capture=True)
2019-02-16 13:19:09,859 - util.py[DEBUG]: Running command ['blkid', '-tLABEL=cidata', '-odevice'] with allowed return codes [0, 2] (shell=False, capture=True)
2019-02-16 13:19:09,864 - handlers.py[DEBUG]: finish: init-local/search-NoCloud: SUCCESS: no local data found from DataSourceNoCloud
2019-02-16 13:19:09,865 - handlers.py[DEBUG]: start: init-local/search-ConfigDrive: searching for local data from DataSourceConfigDrive
2019-02-16 13:19:09,865 - __init__.py[DEBUG]: Seeing if we can get any data from <class 'cloudinit.sources.DataSourceConfigDrive.DataSourceConfigDrive'>
2019-02-16 13:19:09,865 - util.py[DEBUG]: Running command ['blkid', '-odevice', '/dev/sr0'] with allowed return codes [0, 2] (shell=False, capture=True)
2019-02-16 13:19:09,868 - util.py[DEBUG]: Running command ['blkid', '-odevice', '/dev/sr1'] with allowed return codes [0, 2] (shell=False, capture=True)
2019-02-16 13:19:09,870 - util.py[DEBUG]: Running command ['blkid', '-odevice', '/dev/cd0'] with allowed return codes [0, 2] (shell=False, capture=True)
2019-02-16 13:19:09,873 - util.py[DEBUG]: Running command ['blkid', '-odevice', '/dev/cd1'] with allowed return codes [0, 2] (shell=False, capture=True)
2019-02-16 13:19:09,875 - util.py[DEBUG]: Running command ['blkid', '-tTYPE=vfat', '-odevice'] with allowed return codes [0, 2] (shell=False, capture=True)
2019-02-16 13:19:09,881 - util.py[DEBUG]: Running command ['blkid', '-tTYPE=iso9660', '-odevice'] with allowed return codes [0, 2] (shell=False, capture=True)
2019-02-16 13:19:09,886 - util.py[DEBUG]: Running command ['blkid', '-tLABEL=config-2', '-odevice'] with allowed return codes [0, 2] (shell=False, capture=True)
2019-02-16 13:19:09,891 - handlers.py[DEBUG]: finish: init-local/search-ConfigDrive: SUCCESS: no local data found from DataSourceConfigDrive
2019-02-16 13:19:09,892 - handlers.py[DEBUG]: start: init-local/search-OpenNebula: searching for local data from DataSourceOpenNebula
2019-02-16 13:19:09,892 - __init__.py[DEBUG]: Seeing if we can get any data from <class 'cloudinit.sources.DataSourceOpenNebula.DataSourceOpenNebula'>
2019-02-16 13:19:09,892 - util.py[DEBUG]: Running command ['blkid', '-tLABEL=CONTEXT', '-odevice'] with allowed return codes [0, 2] (shell=False, capture=True)
2019-02-16 13:19:09,897 - util.py[DEBUG]: Running command ['blkid', '-tLABEL=CDROM', '-odevice'] with allowed return codes [0, 2] (shell=False, capture=True)
2019-02-16 13:19:09,902 - util.py[DEBUG]: Running command ['blkid', '-tTYPE=iso9660', '-odevice'] with allowed return codes [0, 2] (shell=False, capture=True)
2019-02-16 13:19:09,908 - handlers.py[DEBUG]: finish: init-local/search-OpenNebula: SUCCESS: no local data found from DataSourceOpenNebula
2019-02-16 13:19:09,908 - handlers.py[DEBUG]: start: init-local/search-DigitalOcean: searching for local data from DataSourceDigitalOcean
2019-02-16 13:19:09,908 - __init__.py[DEBUG]: Seeing if we can get any data from <class 'cloudinit.sources.DataSourceDigitalOcean.DataSourceDigitalOcean'>
2019-02-16 13:19:09,908 - util.py[DEBUG]: querying dmi data /sys/class/dmi/id/sys_vendor
2019-02-16 13:19:09,909 - util.py[DEBUG]: Reading from /sys/class/dmi/id/sys_vendor (quiet=False)
2019-02-16 13:19:09,909 - util.py[DEBUG]: Read 4 bytes from /sys/class/dmi/id/sys_vendor
2019-02-16 13:19:09,909 - util.py[DEBUG]: dmi data /sys/class/dmi/id/sys_vendor returned Xen
2019-02-16 13:19:09,909 - handlers.py[DEBUG]: finish: init-local/search-DigitalOcean: SUCCESS: no local data found from DataSourceDigitalOcean
2019-02-16 13:19:09,909 - handlers.py[DEBUG]: start: init-local/search-OVF: searching for local data from DataSourceOVF
2019-02-16 13:19:09,909 - __init__.py[DEBUG]: Seeing if we can get any data from <class 'cloudinit.sources.DataSourceOVF.DataSourceOVF'>
2019-02-16 13:19:09,909 - util.py[DEBUG]: querying dmi data /sys/class/dmi/id/product_name
2019-02-16 13:19:09,910 - util.py[DEBUG]: Reading from /sys/class/dmi/id/product_name (quiet=False)
2019-02-16 13:19:09,910 - util.py[DEBUG]: Read 9 bytes from /sys/class/dmi/id/product_name
2019-02-16 13:19:09,910 - util.py[DEBUG]: dmi data /sys/class/dmi/id/product_name returned HVM domU
2019-02-16 13:19:09,910 - util.py[DEBUG]: Reading from /proc/mounts (quiet=False)
2019-02-16 13:19:09,910 - util.py[DEBUG]: Read 2161 bytes from /proc/mounts
2019-02-16 13:19:09,911 - util.py[DEBUG]: Fetched {'configfs': {'mountpoint': '/sys/kernel/config', 'opts': 'rw,relatime', 'fstype': 'configfs'}, 'devpts': {'mountpoint': '/dev/pts', 'opts': 'rw,seclabel,nosuid,noexec,relatime,gid=5,mode=620,ptmxmode=000', 'fstype': 'devpts'}, 'debugfs': {'mountpoint': '/sys/kernel/debug', 'opts': 'rw,relatime', 'fstype': 'debugfs'}, 'securityfs': {'mountpoint': '/sys/kernel/security', 'opts': 'rw,nosuid,nodev,noexec,relatime', 'fstype': 'securityfs'}, 'sysfs': {'mountpoint': '/sys', 'opts': 'rw,seclabel,nosuid,nodev,noexec,relatime', 'fstype': 'sysfs'}, 'mqueue': {'mountpoint': '/dev/mqueue', 'opts': 'rw,seclabel,relatime', 'fstype': 'mqueue'}, 'pstore': {'mountpoint': '/sys/fs/pstore', 'opts': 'rw,nosuid,nodev,noexec,relatime', 'fstype': 'pstore'}, '/dev/xvda2': {'mountpoint': '/', 'opts': 'rw,seclabel,relatime,attr2,inode64,noquota', 'fstype': 'xfs'}, 'hugetlbfs': {'mountpoint': '/dev/hugepages', 'opts': 'rw,seclabel,relatime', 'fstype': 'hugetlbfs'}, 'systemd-1': {'mountpoint': '/proc/sys/fs/binfmt_misc', 'opts': 'rw,relatime,fd=32,pgrp=1,timeout=0,minproto=5,maxproto=5,direct,pipe_ino=2802', 'fstype': 'autofs'}, 'cgroup': {'mountpoint': '/sys/fs/cgroup/devices', 'opts': 'rw,seclabel,nosuid,nodev,noexec,relatime,devices', 'fstype': 'cgroup'}, 'tmpfs': {'mountpoint': '/sys/fs/cgroup', 'opts': 'ro,seclabel,nosuid,nodev,noexec,mode=755', 'fstype': 'tmpfs'}, 'proc': {'mountpoint': '/proc', 'opts': 'rw,nosuid,nodev,noexec,relatime', 'fstype': 'proc'}, 'devtmpfs': {'mountpoint': '/dev', 'opts': 'rw,seclabel,nosuid,size=8110740k,nr_inodes=2027685,mode=755', 'fstype': 'devtmpfs'}, 'selinuxfs': {'mountpoint': '/sys/fs/selinux', 'opts': 'rw,relatime', 'fstype': 'selinuxfs'}, 'rootfs': {'mountpoint': '/', 'opts': 'rw', 'fstype': 'rootfs'}} mounts from proc
2019-02-16 13:19:09,911 - util.py[DEBUG]: Peeking at /dev/xvda (max_bytes=512)
2019-02-16 13:19:09,911 - util.py[DEBUG]: Reading from /proc/mounts (quiet=False)
2019-02-16 13:19:09,911 - util.py[DEBUG]: Read 2161 bytes from /proc/mounts
2019-02-16 13:19:09,911 - util.py[DEBUG]: Fetched {'configfs': {'mountpoint': '/sys/kernel/config', 'opts': 'rw,relatime', 'fstype': 'configfs'}, 'devpts': {'mountpoint': '/dev/pts', 'opts': 'rw,seclabel,nosuid,noexec,relatime,gid=5,mode=620,ptmxmode=000', 'fstype': 'devpts'}, 'debugfs': {'mountpoint': '/sys/kernel/debug', 'opts': 'rw,relatime', 'fstype': 'debugfs'}, 'securityfs': {'mountpoint': '/sys/kernel/security', 'opts': 'rw,nosuid,nodev,noexec,relatime', 'fstype': 'securityfs'}, 'sysfs': {'mountpoint': '/sys', 'opts': 'rw,seclabel,nosuid,nodev,noexec,relatime', 'fstype': 'sysfs'}, 'mqueue': {'mountpoint': '/dev/mqueue', 'opts': 'rw,seclabel,relatime', 'fstype': 'mqueue'}, 'pstore': {'mountpoint': '/sys/fs/pstore', 'opts': 'rw,nosuid,nodev,noexec,relatime', 'fstype': 'pstore'}, '/dev/xvda2': {'mountpoint': '/', 'opts': 'rw,seclabel,relatime,attr2,inode64,noquota', 'fstype': 'xfs'}, 'hugetlbfs': {'mountpoint': '/dev/hugepages', 'opts': 'rw,seclabel,relatime', 'fstype': 'hugetlbfs'}, 'systemd-1': {'mountpoint': '/proc/sys/fs/binfmt_misc', 'opts': 'rw,relatime,fd=32,pgrp=1,timeout=0,minproto=5,maxproto=5,direct,pipe_ino=2802', 'fstype': 'autofs'}, 'cgroup': {'mountpoint': '/sys/fs/cgroup/devices', 'opts': 'rw,seclabel,nosuid,nodev,noexec,relatime,devices', 'fstype': 'cgroup'}, 'tmpfs': {'mountpoint': '/sys/fs/cgroup', 'opts': 'ro,seclabel,nosuid,nodev,noexec,mode=755', 'fstype': 'tmpfs'}, 'proc': {'mountpoint': '/proc', 'opts': 'rw,nosuid,nodev,noexec,relatime', 'fstype': 'proc'}, 'devtmpfs': {'mountpoint': '/dev', 'opts': 'rw,seclabel,nosuid,size=8110740k,nr_inodes=2027685,mode=755', 'fstype': 'devtmpfs'}, 'selinuxfs': {'mountpoint': '/sys/fs/selinux', 'opts': 'rw,relatime', 'fstype': 'selinuxfs'}, 'rootfs': {'mountpoint': '/', 'opts': 'rw', 'fstype': 'rootfs'}} mounts from proc
2019-02-16 13:19:09,912 - util.py[DEBUG]: Running command ['mount', '-o', 'ro,sync', '-t', 'iso9660', '/dev/xvda', '/tmp/tmpyY2ryb'] with allowed return codes [0] (shell=False, capture=True)
2019-02-16 13:19:09,927 - util.py[DEBUG]: Failed mount of '/dev/xvda' as 'iso9660': Unexpected error while running command.
Command: ['mount', '-o', 'ro,sync', '-t', 'iso9660', '/dev/xvda', '/tmp/tmpyY2ryb']
Exit code: 32
Reason: -
Stdout: -
Stderr: mount: /dev/xvda is already mounted or /tmp/tmpyY2ryb busy
2019-02-16 13:19:09,928 - util.py[DEBUG]: Recursively deleting /tmp/tmpyY2ryb
2019-02-16 13:19:09,928 - DataSourceOVF.py[DEBUG]: /dev/xvda not mountable as iso9660
2019-02-16 13:19:09,928 - util.py[DEBUG]: Peeking at /dev/xvda1 (max_bytes=512)
2019-02-16 13:19:09,929 - util.py[DEBUG]: Reading from /proc/mounts (quiet=False)
2019-02-16 13:19:09,929 - util.py[DEBUG]: Read 2161 bytes from /proc/mounts
2019-02-16 13:19:09,929 - util.py[DEBUG]: Fetched {'configfs': {'mountpoint': '/sys/kernel/config', 'opts': 'rw,relatime', 'fstype': 'configfs'}, 'devpts': {'mountpoint': '/dev/pts', 'opts': 'rw,seclabel,nosuid,noexec,relatime,gid=5,mode=620,ptmxmode=000', 'fstype': 'devpts'}, 'debugfs': {'mountpoint': '/sys/kernel/debug', 'opts': 'rw,relatime', 'fstype': 'debugfs'}, 'securityfs': {'mountpoint': '/sys/kernel/security', 'opts': 'rw,nosuid,nodev,noexec,relatime', 'fstype': 'securityfs'}, 'sysfs': {'mountpoint': '/sys', 'opts': 'rw,seclabel,nosuid,nodev,noexec,relatime', 'fstype': 'sysfs'}, 'mqueue': {'mountpoint': '/dev/mqueue', 'opts': 'rw,seclabel,relatime', 'fstype': 'mqueue'}, 'pstore': {'mountpoint': '/sys/fs/pstore', 'opts': 'rw,nosuid,nodev,noexec,relatime', 'fstype': 'pstore'}, '/dev/xvda2': {'mountpoint': '/', 'opts': 'rw,seclabel,relatime,attr2,inode64,noquota', 'fstype': 'xfs'}, 'hugetlbfs': {'mountpoint': '/dev/hugepages', 'opts': 'rw,seclabel,relatime', 'fstype': 'hugetlbfs'}, 'systemd-1': {'mountpoint': '/proc/sys/fs/binfmt_misc', 'opts': 'rw,relatime,fd=32,pgrp=1,timeout=0,minproto=5,maxproto=5,direct,pipe_ino=2802', 'fstype': 'autofs'}, 'cgroup': {'mountpoint': '/sys/fs/cgroup/devices', 'opts': 'rw,seclabel,nosuid,nodev,noexec,relatime,devices', 'fstype': 'cgroup'}, 'tmpfs': {'mountpoint': '/sys/fs/cgroup', 'opts': 'ro,seclabel,nosuid,nodev,noexec,mode=755', 'fstype': 'tmpfs'}, 'proc': {'mountpoint': '/proc', 'opts': 'rw,nosuid,nodev,noexec,relatime', 'fstype': 'proc'}, 'devtmpfs': {'mountpoint': '/dev', 'opts': 'rw,seclabel,nosuid,size=8110740k,nr_inodes=2027685,mode=755', 'fstype': 'devtmpfs'}, 'selinuxfs': {'mountpoint': '/sys/fs/selinux', 'opts': 'rw,relatime', 'fstype': 'selinuxfs'}, 'rootfs': {'mountpoint': '/', 'opts': 'rw', 'fstype': 'rootfs'}} mounts from proc
2019-02-16 13:19:09,929 - util.py[DEBUG]: Running command ['mount', '-o', 'ro,sync', '-t', 'iso9660', '/dev/xvda1', '/tmp/tmpXc28Xj'] with allowed return codes [0] (shell=False, capture=True)
2019-02-16 13:19:09,954 - util.py[DEBUG]: Failed mount of '/dev/xvda1' as 'iso9660': Unexpected error while running command.
Command: ['mount', '-o', 'ro,sync', '-t', 'iso9660', '/dev/xvda1', '/tmp/tmpXc28Xj']
Exit code: 32
Reason: -
Stdout: -
Stderr: mount: wrong fs type, bad option, bad superblock on /dev/xvda1,
               missing codepage or helper program, or other error
        
               In some cases useful info is found in syslog - try
               dmesg | tail or so.
2019-02-16 13:19:09,954 - util.py[DEBUG]: Recursively deleting /tmp/tmpXc28Xj
2019-02-16 13:19:09,955 - DataSourceOVF.py[DEBUG]: /dev/xvda1 not mountable as iso9660
2019-02-16 13:19:09,955 - handlers.py[DEBUG]: finish: init-local/search-OVF: SUCCESS: no local data found from DataSourceOVF
2019-02-16 13:19:09,955 - handlers.py[DEBUG]: start: init-local/search-CloudSigma: searching for local data from DataSourceCloudSigma
2019-02-16 13:19:09,955 - __init__.py[DEBUG]: Seeing if we can get any data from <class 'cloudinit.sources.DataSourceCloudSigma.DataSourceCloudSigma'>
2019-02-16 13:19:09,955 - DataSourceCloudSigma.py[DEBUG]: determining hypervisor product name via dmi data
2019-02-16 13:19:09,956 - util.py[DEBUG]: querying dmi data /sys/class/dmi/id/product_name
2019-02-16 13:19:09,956 - util.py[DEBUG]: Reading from /sys/class/dmi/id/product_name (quiet=False)
2019-02-16 13:19:09,956 - util.py[DEBUG]: Read 9 bytes from /sys/class/dmi/id/product_name
2019-02-16 13:19:09,956 - util.py[DEBUG]: dmi data /sys/class/dmi/id/product_name returned HVM domU
2019-02-16 13:19:09,956 - DataSourceCloudSigma.py[DEBUG]: detected hypervisor as HVM domU
2019-02-16 13:19:09,956 - handlers.py[DEBUG]: finish: init-local/search-CloudSigma: SUCCESS: no local data found from DataSourceCloudSigma
2019-02-16 13:19:09,956 - handlers.py[DEBUG]: start: init-local/search-SmartOS: searching for local data from DataSourceSmartOS
2019-02-16 13:19:09,956 - __init__.py[DEBUG]: Seeing if we can get any data from <class 'cloudinit.sources.DataSourceSmartOS.DataSourceSmartOS'>
2019-02-16 13:19:09,956 - util.py[DEBUG]: querying dmi data /sys/class/dmi/id/product_name
2019-02-16 13:19:09,957 - util.py[DEBUG]: Reading from /sys/class/dmi/id/product_name (quiet=False)
2019-02-16 13:19:09,957 - util.py[DEBUG]: Read 9 bytes from /sys/class/dmi/id/product_name
2019-02-16 13:19:09,957 - util.py[DEBUG]: dmi data /sys/class/dmi/id/product_name returned HVM domU
2019-02-16 13:19:09,957 - DataSourceSmartOS.py[DEBUG]: Not running on smartos
2019-02-16 13:19:09,957 - handlers.py[DEBUG]: finish: init-local/search-SmartOS: SUCCESS: no local data found from DataSourceSmartOS
2019-02-16 13:19:09,957 - main.py[DEBUG]: No local datasource found
2019-02-16 13:19:09,957 - util.py[DEBUG]: Reading from /sys/class/net/eth0/carrier (quiet=False)
2019-02-16 13:19:09,958 - util.py[DEBUG]: Reading from /sys/class/net/eth0/dormant (quiet=False)
2019-02-16 13:19:09,958 - util.py[DEBUG]: Reading from /sys/class/net/eth0/operstate (quiet=False)
2019-02-16 13:19:09,958 - util.py[DEBUG]: Read 5 bytes from /sys/class/net/eth0/operstate
2019-02-16 13:19:09,958 - util.py[DEBUG]: Reading from /sys/class/net/eth0/address (quiet=False)
2019-02-16 13:19:09,958 - util.py[DEBUG]: Read 18 bytes from /sys/class/net/eth0/address
2019-02-16 13:19:09,958 - stages.py[DEBUG]: applying net config names for {'version': 1, 'config': [{'subnets': [{'type': 'dhcp'}], 'type': 'physical', 'name': 'eth0', 'mac_address': '02:a3:bc:dc:d6:e6'}]}
2019-02-16 13:19:09,958 - util.py[DEBUG]: Reading from /sys/class/net/lo/addr_assign_type (quiet=False)
2019-02-16 13:19:09,958 - util.py[DEBUG]: Read 2 bytes from /sys/class/net/lo/addr_assign_type
2019-02-16 13:19:09,958 - util.py[DEBUG]: Reading from /sys/class/net/lo/address (quiet=False)
2019-02-16 13:19:09,959 - util.py[DEBUG]: Read 18 bytes from /sys/class/net/lo/address
2019-02-16 13:19:09,959 - util.py[DEBUG]: Reading from /sys/class/net/eth0/addr_assign_type (quiet=False)
2019-02-16 13:19:09,959 - util.py[DEBUG]: Read 2 bytes from /sys/class/net/eth0/addr_assign_type
2019-02-16 13:19:09,959 - util.py[DEBUG]: Reading from /sys/class/net/eth0/address (quiet=False)
2019-02-16 13:19:09,959 - util.py[DEBUG]: Read 18 bytes from /sys/class/net/eth0/address
2019-02-16 13:19:09,959 - util.py[DEBUG]: Reading from /sys/class/net/eth0/operstate (quiet=False)
2019-02-16 13:19:09,959 - util.py[DEBUG]: Read 5 bytes from /sys/class/net/eth0/operstate
2019-02-16 13:19:09,959 - util.py[DEBUG]: Reading from /sys/class/net/lo/operstate (quiet=False)
2019-02-16 13:19:09,959 - util.py[DEBUG]: Read 8 bytes from /sys/class/net/lo/operstate
2019-02-16 13:19:09,960 - util.py[DEBUG]: Running command ['ip', '-6', 'addr', 'show', 'permanent', 'scope', 'global'] with allowed return codes [0] (shell=False, capture=True)
2019-02-16 13:19:09,968 - util.py[DEBUG]: Running command ['ip', '-4', 'addr', 'show'] with allowed return codes [0] (shell=False, capture=True)
2019-02-16 13:19:09,972 - __init__.py[DEBUG]: no work necessary for renaming of [['02:a3:bc:dc:d6:e6', 'eth0']]
2019-02-16 13:19:09,972 - stages.py[INFO]: Applying network configuration from fallback bringup=False: {'version': 1, 'config': [{'subnets': [{'type': 'dhcp'}], 'type': 'physical', 'name': 'eth0', 'mac_address': '02:a3:bc:dc:d6:e6'}]}
2019-02-16 13:19:09,975 - util.py[DEBUG]: Writing to /etc/sysconfig/network-scripts/ifcfg-eth0 - wb: [420] 159 bytes
2019-02-16 13:19:09,975 - util.py[DEBUG]: Restoring selinux mode for /etc/sysconfig/network-scripts/ifcfg-eth0 (recursive=False)
2019-02-16 13:19:09,975 - util.py[DEBUG]: Restoring selinux mode for /etc/sysconfig/network-scripts/ifcfg-eth0 (recursive=False)
2019-02-16 13:19:09,976 - util.py[DEBUG]: Reading from /etc/resolv.conf (quiet=False)
2019-02-16 13:19:09,976 - util.py[DEBUG]: Read 55 bytes from /etc/resolv.conf
2019-02-16 13:19:09,976 - util.py[DEBUG]: Writing to /etc/resolv.conf - wb: [420] 126 bytes
2019-02-16 13:19:09,976 - util.py[DEBUG]: Restoring selinux mode for /etc/resolv.conf (recursive=False)
2019-02-16 13:19:09,977 - util.py[DEBUG]: Restoring selinux mode for /etc/resolv.conf (recursive=False)
2019-02-16 13:19:09,977 - util.py[DEBUG]: Writing to /etc/udev/rules.d/70-persistent-net.rules - wb: [420] 96 bytes
2019-02-16 13:19:09,977 - util.py[DEBUG]: Restoring selinux mode for /etc/udev/rules.d/70-persistent-net.rules (recursive=False)
2019-02-16 13:19:09,978 - util.py[DEBUG]: Restoring selinux mode for /etc/udev/rules.d/70-persistent-net.rules (recursive=False)
2019-02-16 13:19:09,978 - main.py[DEBUG]: [local] Exiting without datasource in local mode
2019-02-16 13:19:09,979 - util.py[DEBUG]: Reading from /proc/uptime (quiet=False)
2019-02-16 13:19:09,979 - util.py[DEBUG]: Read 11 bytes from /proc/uptime
2019-02-16 13:19:09,979 - util.py[DEBUG]: cloud-init mode 'init' took 0.285 seconds (0.29)
2019-02-16 13:19:09,979 - handlers.py[DEBUG]: finish: init-local: SUCCESS: searching for local datasources
2019-02-16 13:19:10,833 - util.py[DEBUG]: Cloud-init v. 0.7.9 running 'init' at Sat, 16 Feb 2019 13:19:10 +0000. Up 7.30 seconds.
2019-02-16 13:19:10,834 - util.py[DEBUG]: Restoring selinux mode for /var/lib/cloud (recursive=False)
2019-02-16 13:19:10,835 - util.py[DEBUG]: Restoring selinux mode for /var/lib/cloud/scripts (recursive=False)
2019-02-16 13:19:10,836 - util.py[DEBUG]: Restoring selinux mode for /var/lib/cloud/scripts/per-instance (recursive=False)
2019-02-16 13:19:10,836 - util.py[DEBUG]: Restoring selinux mode for /var/lib/cloud/scripts/per-once (recursive=False)
2019-02-16 13:19:10,837 - util.py[DEBUG]: Restoring selinux mode for /var/lib/cloud/scripts/per-boot (recursive=False)
2019-02-16 13:19:10,838 - util.py[DEBUG]: Restoring selinux mode for /var/lib/cloud/scripts/vendor (recursive=False)
2019-02-16 13:19:10,839 - util.py[DEBUG]: Restoring selinux mode for /var/lib/cloud/seed (recursive=False)
2019-02-16 13:19:10,839 - util.py[DEBUG]: Restoring selinux mode for /var/lib/cloud/instances (recursive=False)
2019-02-16 13:19:10,840 - util.py[DEBUG]: Restoring selinux mode for /var/lib/cloud/handlers (recursive=False)
2019-02-16 13:19:10,841 - util.py[DEBUG]: Restoring selinux mode for /var/lib/cloud/sem (recursive=False)
2019-02-16 13:19:10,841 - util.py[DEBUG]: Restoring selinux mode for /var/lib/cloud/data (recursive=False)
2019-02-16 13:19:10,842 - util.py[DEBUG]: Writing to /var/log/cloud-init.log - ab: [384] 0 bytes
2019-02-16 13:19:10,842 - util.py[DEBUG]: Restoring selinux mode for /var/log/cloud-init.log (recursive=False)
2019-02-16 13:19:10,843 - util.py[DEBUG]: Restoring selinux mode for /var/log/cloud-init.log (recursive=False)
2019-02-16 13:19:10,843 - util.py[DEBUG]: Running command ['ifconfig', '-a'] with allowed return codes [0] (shell=False, capture=True)
2019-02-16 13:19:10,854 - util.py[DEBUG]: Running command ['netstat', '-rn'] with allowed return codes [0] (shell=False, capture=True)
2019-02-16 13:19:10,860 - util.py[DEBUG]: Running command ['netstat', '-A', 'inet6', '-n'] with allowed return codes [0] (shell=False, capture=True)
2019-02-16 13:19:10,866 - main.py[DEBUG]: Checking to see if files that we need already exist from a previous run that would allow us to stop early.
2019-02-16 13:19:10,866 - main.py[DEBUG]: Execution continuing, no previous run detected that would allow us to stop early.
2019-02-16 13:19:10,866 - handlers.py[DEBUG]: start: init-network/check-cache: attempting to read from cache [trust]
2019-02-16 13:19:10,866 - util.py[DEBUG]: Reading from /var/lib/cloud/instance/obj.pkl (quiet=False)
2019-02-16 13:19:10,867 - stages.py[DEBUG]: no cache found
2019-02-16 13:19:10,867 - handlers.py[DEBUG]: finish: init-network/check-cache: SUCCESS: no cache found
2019-02-16 13:19:10,867 - util.py[DEBUG]: Attempting to remove /var/lib/cloud/instance
2019-02-16 13:19:10,882 - stages.py[DEBUG]: Using distro class <class 'cloudinit.distros.rhel.Distro'>
2019-02-16 13:19:10,882 - __init__.py[DEBUG]: Looking for for data source in: ['NoCloud', 'ConfigDrive', 'OpenNebula', 'DigitalOcean', 'Azure', 'AltCloud', 'OVF', 'MAAS', 'GCE', 'OpenStack', 'AliYun', 'Ec2', 'CloudSigma', 'CloudStack', 'SmartOS', 'Bigstep', 'None'], via packages ['', u'cloudinit.sources'] that matches dependencies ['FILESYSTEM', 'NETWORK']
2019-02-16 13:19:10,932 - __init__.py[DEBUG]: Searching for network data source in: [u'DataSourceNoCloudNet', u'DataSourceAzureNet', u'DataSourceAltCloud', u'DataSourceOVFNet', u'DataSourceMAAS', u'DataSourceGCE', u'DataSourceOpenStack', u'DataSourceAliYun', u'DataSourceEc2', u'DataSourceCloudStack', u'DataSourceBigstep', u'DataSourceNone']
2019-02-16 13:19:10,933 - handlers.py[DEBUG]: start: init-network/search-NoCloudNet: searching for network data from DataSourceNoCloudNet
2019-02-16 13:19:10,933 - __init__.py[DEBUG]: Seeing if we can get any data from <class 'cloudinit.sources.DataSourceNoCloud.DataSourceNoCloudNet'>
2019-02-16 13:19:10,933 - util.py[DEBUG]: Reading from /var/lib/cloud/seed/nocloud/user-data (quiet=False)
2019-02-16 13:19:10,933 - util.py[DEBUG]: Reading from /var/lib/cloud/seed/nocloud/meta-data (quiet=False)
2019-02-16 13:19:10,933 - util.py[DEBUG]: Reading from /var/lib/cloud/seed/nocloud/vendor-data (quiet=False)
2019-02-16 13:19:10,933 - util.py[DEBUG]: Reading from /var/lib/cloud/seed/nocloud/network-config (quiet=False)
2019-02-16 13:19:10,933 - util.py[DEBUG]: Reading from /var/lib/cloud/seed/nocloud-net/user-data (quiet=False)
2019-02-16 13:19:10,933 - util.py[DEBUG]: Reading from /var/lib/cloud/seed/nocloud-net/meta-data (quiet=False)
2019-02-16 13:19:10,933 - util.py[DEBUG]: Reading from /var/lib/cloud/seed/nocloud-net/vendor-data (quiet=False)
2019-02-16 13:19:10,933 - util.py[DEBUG]: Reading from /var/lib/cloud/seed/nocloud-net/network-config (quiet=False)
2019-02-16 13:19:10,934 - util.py[DEBUG]: Running command ['blkid', '-odevice', '/dev/sr0'] with allowed return codes [0, 2] (shell=False, capture=True)
2019-02-16 13:19:10,939 - util.py[DEBUG]: Running command ['blkid', '-odevice', '/dev/sr1'] with allowed return codes [0, 2] (shell=False, capture=True)
2019-02-16 13:19:10,942 - util.py[DEBUG]: Running command ['blkid', '-tTYPE=vfat', '-odevice'] with allowed return codes [0, 2] (shell=False, capture=True)
2019-02-16 13:19:10,949 - util.py[DEBUG]: Running command ['blkid', '-tTYPE=iso9660', '-odevice'] with allowed return codes [0, 2] (shell=False, capture=True)
2019-02-16 13:19:10,957 - util.py[DEBUG]: Running command ['blkid', '-tLABEL=cidata', '-odevice'] with allowed return codes [0, 2] (shell=False, capture=True)
2019-02-16 13:19:10,964 - handlers.py[DEBUG]: finish: init-network/search-NoCloudNet: SUCCESS: no network data found from DataSourceNoCloudNet
2019-02-16 13:19:10,965 - handlers.py[DEBUG]: start: init-network/search-AzureNet: searching for network data from DataSourceAzureNet
2019-02-16 13:19:10,965 - __init__.py[DEBUG]: Seeing if we can get any data from <class 'cloudinit.sources.DataSourceAzure.DataSourceAzureNet'>
2019-02-16 13:19:10,965 - util.py[DEBUG]: Running command ['blkid', '-tTYPE=iso9660', '-odevice'] with allowed return codes [0, 2] (shell=False, capture=True)
2019-02-16 13:19:10,972 - util.py[DEBUG]: Running command ['blkid', '-tTYPE=udf', '-odevice'] with allowed return codes [0, 2] (shell=False, capture=True)
2019-02-16 13:19:10,980 - handlers.py[DEBUG]: finish: init-network/search-AzureNet: SUCCESS: no network data found from DataSourceAzureNet
2019-02-16 13:19:10,980 - handlers.py[DEBUG]: start: init-network/search-AltCloud: searching for network data from DataSourceAltCloud
2019-02-16 13:19:10,980 - __init__.py[DEBUG]: Seeing if we can get any data from <class 'cloudinit.sources.DataSourceAltCloud.DataSourceAltCloud'>
2019-02-16 13:19:10,980 - DataSourceAltCloud.py[DEBUG]: Invoked get_data()
2019-02-16 13:19:10,980 - util.py[DEBUG]: querying dmi data /sys/class/dmi/id/product_name
2019-02-16 13:19:10,981 - util.py[DEBUG]: Reading from /sys/class/dmi/id/product_name (quiet=False)
2019-02-16 13:19:10,981 - util.py[DEBUG]: Read 9 bytes from /sys/class/dmi/id/product_name
2019-02-16 13:19:10,981 - util.py[DEBUG]: dmi data /sys/class/dmi/id/product_name returned HVM domU
2019-02-16 13:19:10,981 - DataSourceAltCloud.py[DEBUG]: cloud_type: UNKNOWN
2019-02-16 13:19:10,982 - handlers.py[DEBUG]: finish: init-network/search-AltCloud: SUCCESS: no network data found from DataSourceAltCloud
2019-02-16 13:19:10,982 - handlers.py[DEBUG]: start: init-network/search-OVFNet: searching for network data from DataSourceOVFNet
2019-02-16 13:19:10,982 - __init__.py[DEBUG]: Seeing if we can get any data from <class 'cloudinit.sources.DataSourceOVF.DataSourceOVFNet'>
2019-02-16 13:19:10,982 - util.py[DEBUG]: querying dmi data /sys/class/dmi/id/product_name
2019-02-16 13:19:10,982 - util.py[DEBUG]: Reading from /sys/class/dmi/id/product_name (quiet=False)
2019-02-16 13:19:10,982 - util.py[DEBUG]: Read 9 bytes from /sys/class/dmi/id/product_name
2019-02-16 13:19:10,982 - util.py[DEBUG]: dmi data /sys/class/dmi/id/product_name returned HVM domU
2019-02-16 13:19:10,983 - util.py[DEBUG]: Reading from /proc/mounts (quiet=False)
2019-02-16 13:19:10,983 - util.py[DEBUG]: Read 2161 bytes from /proc/mounts
2019-02-16 13:19:10,984 - util.py[DEBUG]: Fetched {'configfs': {'mountpoint': '/sys/kernel/config', 'opts': 'rw,relatime', 'fstype': 'configfs'}, 'devpts': {'mountpoint': '/dev/pts', 'opts': 'rw,seclabel,nosuid,noexec,relatime,gid=5,mode=620,ptmxmode=000', 'fstype': 'devpts'}, 'debugfs': {'mountpoint': '/sys/kernel/debug', 'opts': 'rw,relatime', 'fstype': 'debugfs'}, 'securityfs': {'mountpoint': '/sys/kernel/security', 'opts': 'rw,nosuid,nodev,noexec,relatime', 'fstype': 'securityfs'}, 'sysfs': {'mountpoint': '/sys', 'opts': 'rw,seclabel,nosuid,nodev,noexec,relatime', 'fstype': 'sysfs'}, 'mqueue': {'mountpoint': '/dev/mqueue', 'opts': 'rw,seclabel,relatime', 'fstype': 'mqueue'}, 'pstore': {'mountpoint': '/sys/fs/pstore', 'opts': 'rw,nosuid,nodev,noexec,relatime', 'fstype': 'pstore'}, '/dev/xvda2': {'mountpoint': '/', 'opts': 'rw,seclabel,relatime,attr2,inode64,noquota', 'fstype': 'xfs'}, 'hugetlbfs': {'mountpoint': '/dev/hugepages', 'opts': 'rw,seclabel,relatime', 'fstype': 'hugetlbfs'}, 'systemd-1': {'mountpoint': '/proc/sys/fs/binfmt_misc', 'opts': 'rw,relatime,fd=32,pgrp=1,timeout=0,minproto=5,maxproto=5,direct,pipe_ino=2802', 'fstype': 'autofs'}, 'cgroup': {'mountpoint': '/sys/fs/cgroup/devices', 'opts': 'rw,seclabel,nosuid,nodev,noexec,relatime,devices', 'fstype': 'cgroup'}, 'tmpfs': {'mountpoint': '/sys/fs/cgroup', 'opts': 'ro,seclabel,nosuid,nodev,noexec,mode=755', 'fstype': 'tmpfs'}, 'proc': {'mountpoint': '/proc', 'opts': 'rw,nosuid,nodev,noexec,relatime', 'fstype': 'proc'}, 'devtmpfs': {'mountpoint': '/dev', 'opts': 'rw,seclabel,nosuid,size=8110740k,nr_inodes=2027685,mode=755', 'fstype': 'devtmpfs'}, 'selinuxfs': {'mountpoint': '/sys/fs/selinux', 'opts': 'rw,relatime', 'fstype': 'selinuxfs'}, 'rootfs': {'mountpoint': '/', 'opts': 'rw', 'fstype': 'rootfs'}} mounts from proc
2019-02-16 13:19:10,984 - util.py[DEBUG]: Peeking at /dev/xvda (max_bytes=512)
2019-02-16 13:19:10,985 - util.py[DEBUG]: Reading from /proc/mounts (quiet=False)
2019-02-16 13:19:10,985 - util.py[DEBUG]: Read 2161 bytes from /proc/mounts
2019-02-16 13:19:10,985 - util.py[DEBUG]: Fetched {'configfs': {'mountpoint': '/sys/kernel/config', 'opts': 'rw,relatime', 'fstype': 'configfs'}, 'devpts': {'mountpoint': '/dev/pts', 'opts': 'rw,seclabel,nosuid,noexec,relatime,gid=5,mode=620,ptmxmode=000', 'fstype': 'devpts'}, 'debugfs': {'mountpoint': '/sys/kernel/debug', 'opts': 'rw,relatime', 'fstype': 'debugfs'}, 'securityfs': {'mountpoint': '/sys/kernel/security', 'opts': 'rw,nosuid,nodev,noexec,relatime', 'fstype': 'securityfs'}, 'sysfs': {'mountpoint': '/sys', 'opts': 'rw,seclabel,nosuid,nodev,noexec,relatime', 'fstype': 'sysfs'}, 'mqueue': {'mountpoint': '/dev/mqueue', 'opts': 'rw,seclabel,relatime', 'fstype': 'mqueue'}, 'pstore': {'mountpoint': '/sys/fs/pstore', 'opts': 'rw,nosuid,nodev,noexec,relatime', 'fstype': 'pstore'}, '/dev/xvda2': {'mountpoint': '/', 'opts': 'rw,seclabel,relatime,attr2,inode64,noquota', 'fstype': 'xfs'}, 'hugetlbfs': {'mountpoint': '/dev/hugepages', 'opts': 'rw,seclabel,relatime', 'fstype': 'hugetlbfs'}, 'systemd-1': {'mountpoint': '/proc/sys/fs/binfmt_misc', 'opts': 'rw,relatime,fd=32,pgrp=1,timeout=0,minproto=5,maxproto=5,direct,pipe_ino=2802', 'fstype': 'autofs'}, 'cgroup': {'mountpoint': '/sys/fs/cgroup/devices', 'opts': 'rw,seclabel,nosuid,nodev,noexec,relatime,devices', 'fstype': 'cgroup'}, 'tmpfs': {'mountpoint': '/sys/fs/cgroup', 'opts': 'ro,seclabel,nosuid,nodev,noexec,mode=755', 'fstype': 'tmpfs'}, 'proc': {'mountpoint': '/proc', 'opts': 'rw,nosuid,nodev,noexec,relatime', 'fstype': 'proc'}, 'devtmpfs': {'mountpoint': '/dev', 'opts': 'rw,seclabel,nosuid,size=8110740k,nr_inodes=2027685,mode=755', 'fstype': 'devtmpfs'}, 'selinuxfs': {'mountpoint': '/sys/fs/selinux', 'opts': 'rw,relatime', 'fstype': 'selinuxfs'}, 'rootfs': {'mountpoint': '/', 'opts': 'rw', 'fstype': 'rootfs'}} mounts from proc
2019-02-16 13:19:10,986 - util.py[DEBUG]: Running command ['mount', '-o', 'ro,sync', '-t', 'iso9660', '/dev/xvda', '/tmp/tmpLweqSh'] with allowed return codes [0] (shell=False, capture=True)
2019-02-16 13:19:10,997 - util.py[DEBUG]: Failed mount of '/dev/xvda' as 'iso9660': Unexpected error while running command.
Command: ['mount', '-o', 'ro,sync', '-t', 'iso9660', '/dev/xvda', '/tmp/tmpLweqSh']
Exit code: 32
Reason: -
Stdout: -
Stderr: mount: /dev/xvda is already mounted or /tmp/tmpLweqSh busy
2019-02-16 13:19:10,997 - util.py[DEBUG]: Recursively deleting /tmp/tmpLweqSh
2019-02-16 13:19:10,997 - DataSourceOVF.py[DEBUG]: /dev/xvda not mountable as iso9660
2019-02-16 13:19:10,998 - util.py[DEBUG]: Peeking at /dev/xvda1 (max_bytes=512)
2019-02-16 13:19:10,998 - util.py[DEBUG]: Reading from /proc/mounts (quiet=False)
2019-02-16 13:19:10,999 - util.py[DEBUG]: Read 2161 bytes from /proc/mounts
2019-02-16 13:19:10,999 - util.py[DEBUG]: Fetched {'configfs': {'mountpoint': '/sys/kernel/config', 'opts': 'rw,relatime', 'fstype': 'configfs'}, 'devpts': {'mountpoint': '/dev/pts', 'opts': 'rw,seclabel,nosuid,noexec,relatime,gid=5,mode=620,ptmxmode=000', 'fstype': 'devpts'}, 'debugfs': {'mountpoint': '/sys/kernel/debug', 'opts': 'rw,relatime', 'fstype': 'debugfs'}, 'securityfs': {'mountpoint': '/sys/kernel/security', 'opts': 'rw,nosuid,nodev,noexec,relatime', 'fstype': 'securityfs'}, 'sysfs': {'mountpoint': '/sys', 'opts': 'rw,seclabel,nosuid,nodev,noexec,relatime', 'fstype': 'sysfs'}, 'mqueue': {'mountpoint': '/dev/mqueue', 'opts': 'rw,seclabel,relatime', 'fstype': 'mqueue'}, 'pstore': {'mountpoint': '/sys/fs/pstore', 'opts': 'rw,nosuid,nodev,noexec,relatime', 'fstype': 'pstore'}, '/dev/xvda2': {'mountpoint': '/', 'opts': 'rw,seclabel,relatime,attr2,inode64,noquota', 'fstype': 'xfs'}, 'hugetlbfs': {'mountpoint': '/dev/hugepages', 'opts': 'rw,seclabel,relatime', 'fstype': 'hugetlbfs'}, 'systemd-1': {'mountpoint': '/proc/sys/fs/binfmt_misc', 'opts': 'rw,relatime,fd=32,pgrp=1,timeout=0,minproto=5,maxproto=5,direct,pipe_ino=2802', 'fstype': 'autofs'}, 'cgroup': {'mountpoint': '/sys/fs/cgroup/devices', 'opts': 'rw,seclabel,nosuid,nodev,noexec,relatime,devices', 'fstype': 'cgroup'}, 'tmpfs': {'mountpoint': '/sys/fs/cgroup', 'opts': 'ro,seclabel,nosuid,nodev,noexec,mode=755', 'fstype': 'tmpfs'}, 'proc': {'mountpoint': '/proc', 'opts': 'rw,nosuid,nodev,noexec,relatime', 'fstype': 'proc'}, 'devtmpfs': {'mountpoint': '/dev', 'opts': 'rw,seclabel,nosuid,size=8110740k,nr_inodes=2027685,mode=755', 'fstype': 'devtmpfs'}, 'selinuxfs': {'mountpoint': '/sys/fs/selinux', 'opts': 'rw,relatime', 'fstype': 'selinuxfs'}, 'rootfs': {'mountpoint': '/', 'opts': 'rw', 'fstype': 'rootfs'}} mounts from proc
2019-02-16 13:19:10,999 - util.py[DEBUG]: Running command ['mount', '-o', 'ro,sync', '-t', 'iso9660', '/dev/xvda1', '/tmp/tmpwStapA'] with allowed return codes [0] (shell=False, capture=True)
2019-02-16 13:19:11,027 - util.py[DEBUG]: Failed mount of '/dev/xvda1' as 'iso9660': Unexpected error while running command.
Command: ['mount', '-o', 'ro,sync', '-t', 'iso9660', '/dev/xvda1', '/tmp/tmpwStapA']
Exit code: 32
Reason: -
Stdout: -
Stderr: mount: wrong fs type, bad option, bad superblock on /dev/xvda1,
               missing codepage or helper program, or other error
        
               In some cases useful info is found in syslog - try
               dmesg | tail or so.
2019-02-16 13:19:11,027 - util.py[DEBUG]: Recursively deleting /tmp/tmpwStapA
2019-02-16 13:19:11,028 - DataSourceOVF.py[DEBUG]: /dev/xvda1 not mountable as iso9660
2019-02-16 13:19:11,028 - handlers.py[DEBUG]: finish: init-network/search-OVFNet: SUCCESS: no network data found from DataSourceOVFNet
2019-02-16 13:19:11,028 - handlers.py[DEBUG]: start: init-network/search-MAAS: searching for network data from DataSourceMAAS
2019-02-16 13:19:11,028 - __init__.py[DEBUG]: Seeing if we can get any data from <class 'cloudinit.sources.DataSourceMAAS.DataSourceMAAS'>
2019-02-16 13:19:11,029 - handlers.py[DEBUG]: finish: init-network/search-MAAS: SUCCESS: no network data found from DataSourceMAAS
2019-02-16 13:19:11,029 - handlers.py[DEBUG]: start: init-network/search-GCE: searching for network data from DataSourceGCE
2019-02-16 13:19:11,029 - __init__.py[DEBUG]: Seeing if we can get any data from <class 'cloudinit.sources.DataSourceGCE.DataSourceGCE'>
2019-02-16 13:19:11,086 - DataSourceGCE.py[DEBUG]: http://metadata.google.internal/computeMetadata/v1/ is not resolvable
2019-02-16 13:19:11,086 - handlers.py[DEBUG]: finish: init-network/search-GCE: SUCCESS: no network data found from DataSourceGCE
2019-02-16 13:19:11,087 - handlers.py[DEBUG]: start: init-network/search-OpenStack: searching for network data from DataSourceOpenStack
2019-02-16 13:19:11,087 - __init__.py[DEBUG]: Seeing if we can get any data from <class 'cloudinit.sources.DataSourceOpenStack.DataSourceOpenStack'>
2019-02-16 13:19:11,087 - url_helper.py[DEBUG]: [0/1] open 'http://169.254.169.254/openstack' with {'url': 'http://169.254.169.254/openstack', 'headers': {'User-Agent': 'Cloud-Init/0.7.9'}, 'allow_redirects': True, 'method': 'GET', 'timeout': 10.0} configuration
2019-02-16 13:19:11,099 - url_helper.py[DEBUG]: Read from http://169.254.169.254/openstack (404, 345b) after 1 attempts
2019-02-16 13:19:11,099 - url_helper.py[DEBUG]: Calling 'http://169.254.169.254/openstack' failed [0/-1s]: bad status code [404]
2019-02-16 13:19:11,099 - DataSourceOpenStack.py[DEBUG]: Giving up on OpenStack md from ['http://169.254.169.254/openstack'] after 0 seconds
2019-02-16 13:19:11,100 - handlers.py[DEBUG]: finish: init-network/search-OpenStack: SUCCESS: no network data found from DataSourceOpenStack
2019-02-16 13:19:11,100 - handlers.py[DEBUG]: start: init-network/search-AliYun: searching for network data from DataSourceAliYun
2019-02-16 13:19:11,100 - __init__.py[DEBUG]: Seeing if we can get any data from <class 'cloudinit.sources.DataSourceAliYun.DataSourceAliYun'>
2019-02-16 13:19:11,100 - util.py[DEBUG]: Reading from /var/lib/cloud/seed/AliYun/meta-data (quiet=False)
2019-02-16 13:19:11,100 - util.py[DEBUG]: querying dmi data /sys/class/dmi/id/product_name
2019-02-16 13:19:11,100 - util.py[DEBUG]: Reading from /sys/class/dmi/id/product_name (quiet=False)
2019-02-16 13:19:11,100 - util.py[DEBUG]: Read 9 bytes from /sys/class/dmi/id/product_name
2019-02-16 13:19:11,100 - util.py[DEBUG]: dmi data /sys/class/dmi/id/product_name returned HVM domU
2019-02-16 13:19:11,100 - DataSourceEc2.py[DEBUG]: strict_mode: warn, cloud_platform=No-EC2-Metadata
2019-02-16 13:19:11,101 - handlers.py[DEBUG]: finish: init-network/search-AliYun: SUCCESS: no network data found from DataSourceAliYun
2019-02-16 13:19:11,101 - handlers.py[DEBUG]: start: init-network/search-Ec2: searching for network data from DataSourceEc2
2019-02-16 13:19:11,101 - __init__.py[DEBUG]: Seeing if we can get any data from <class 'cloudinit.sources.DataSourceEc2.DataSourceEc2'>
2019-02-16 13:19:11,101 - util.py[DEBUG]: Reading from /var/lib/cloud/seed/ec2/meta-data (quiet=False)
2019-02-16 13:19:11,101 - util.py[DEBUG]: Reading from /sys/hypervisor/uuid (quiet=False)
2019-02-16 13:19:11,101 - util.py[DEBUG]: Read 37 bytes from /sys/hypervisor/uuid
2019-02-16 13:19:11,101 - util.py[DEBUG]: querying dmi data /sys/class/dmi/id/product_serial
2019-02-16 13:19:11,101 - util.py[DEBUG]: Reading from /sys/class/dmi/id/product_serial (quiet=False)
2019-02-16 13:19:11,101 - util.py[DEBUG]: Read 37 bytes from /sys/class/dmi/id/product_serial
2019-02-16 13:19:11,101 - util.py[DEBUG]: dmi data /sys/class/dmi/id/product_serial returned ec205d73-2926-98df-43fa-ff17bf356219
2019-02-16 13:19:11,101 - DataSourceEc2.py[DEBUG]: strict_mode: warn, cloud_platform=AWS
2019-02-16 13:19:11,103 - DataSourceEc2.py[DEBUG]: Removed the following from metadata urls: ['http://instance-data.:8773']
2019-02-16 13:19:11,103 - url_helper.py[DEBUG]: [0/1] open 'http://169.254.169.254/2009-04-04/meta-data/instance-id' with {'url': 'http://169.254.169.254/2009-04-04/meta-data/instance-id', 'headers': {'User-Agent': 'Cloud-Init/0.7.9'}, 'allow_redirects': True, 'method': 'GET', 'timeout': 50.0} configuration
2019-02-16 13:19:11,105 - url_helper.py[DEBUG]: Read from http://169.254.169.254/2009-04-04/meta-data/instance-id (200, 19b) after 1 attempts
2019-02-16 13:19:11,105 - DataSourceEc2.py[DEBUG]: Using metadata source: 'http://169.254.169.254'
2019-02-16 13:19:11,105 - url_helper.py[DEBUG]: [0/6] open 'http://169.254.169.254/2009-04-04/user-data' with {'url': 'http://169.254.169.254/2009-04-04/user-data', 'headers': {'User-Agent': 'Cloud-Init/0.7.9'}, 'allow_redirects': True, 'method': 'GET', 'timeout': 5.0} configuration
2019-02-16 13:19:11,107 - url_helper.py[DEBUG]: Read from http://169.254.169.254/2009-04-04/user-data (200, 2734b) after 1 attempts
2019-02-16 13:19:11,107 - url_helper.py[DEBUG]: [0/6] open 'http://169.254.169.254/2009-04-04/meta-data/' with {'url': 'http://169.254.169.254/2009-04-04/meta-data/', 'headers': {'User-Agent': 'Cloud-Init/0.7.9'}, 'allow_redirects': True, 'method': 'GET', 'timeout': 5.0} configuration
2019-02-16 13:19:11,109 - url_helper.py[DEBUG]: Read from http://169.254.169.254/2009-04-04/meta-data/ (200, 231b) after 1 attempts
2019-02-16 13:19:11,109 - url_helper.py[DEBUG]: [0/6] open 'http://169.254.169.254/2009-04-04/meta-data/block-device-mapping/' with {'url': 'http://169.254.169.254/2009-04-04/meta-data/block-device-mapping/', 'headers': {'User-Agent': 'Cloud-Init/0.7.9'}, 'allow_redirects': True, 'method': 'GET', 'timeout': 5.0} configuration
2019-02-16 13:19:11,111 - url_helper.py[DEBUG]: Read from http://169.254.169.254/2009-04-04/meta-data/block-device-mapping/ (200, 8b) after 1 attempts
2019-02-16 13:19:11,111 - url_helper.py[DEBUG]: [0/6] open 'http://169.254.169.254/2009-04-04/meta-data/block-device-mapping/ami' with {'url': 'http://169.254.169.254/2009-04-04/meta-data/block-device-mapping/ami', 'headers': {'User-Agent': 'Cloud-Init/0.7.9'}, 'allow_redirects': True, 'method': 'GET', 'timeout': 5.0} configuration
2019-02-16 13:19:11,113 - url_helper.py[DEBUG]: Read from http://169.254.169.254/2009-04-04/meta-data/block-device-mapping/ami (200, 9b) after 1 attempts
2019-02-16 13:19:11,113 - url_helper.py[DEBUG]: [0/6] open 'http://169.254.169.254/2009-04-04/meta-data/block-device-mapping/root' with {'url': 'http://169.254.169.254/2009-04-04/meta-data/block-device-mapping/root', 'headers': {'User-Agent': 'Cloud-Init/0.7.9'}, 'allow_redirects': True, 'method': 'GET', 'timeout': 5.0} configuration
2019-02-16 13:19:11,115 - url_helper.py[DEBUG]: Read from http://169.254.169.254/2009-04-04/meta-data/block-device-mapping/root (200, 9b) after 1 attempts
2019-02-16 13:19:11,115 - url_helper.py[DEBUG]: [0/6] open 'http://169.254.169.254/2009-04-04/meta-data/placement/' with {'url': 'http://169.254.169.254/2009-04-04/meta-data/placement/', 'headers': {'User-Agent': 'Cloud-Init/0.7.9'}, 'allow_redirects': True, 'method': 'GET', 'timeout': 5.0} configuration
2019-02-16 13:19:11,117 - url_helper.py[DEBUG]: Read from http://169.254.169.254/2009-04-04/meta-data/placement/ (200, 17b) after 1 attempts
2019-02-16 13:19:11,117 - url_helper.py[DEBUG]: [0/6] open 'http://169.254.169.254/2009-04-04/meta-data/placement/availability-zone' with {'url': 'http://169.254.169.254/2009-04-04/meta-data/placement/availability-zone', 'headers': {'User-Agent': 'Cloud-Init/0.7.9'}, 'allow_redirects': True, 'method': 'GET', 'timeout': 5.0} configuration
2019-02-16 13:19:11,119 - url_helper.py[DEBUG]: Read from http://169.254.169.254/2009-04-04/meta-data/placement/availability-zone (200, 10b) after 1 attempts
2019-02-16 13:19:11,119 - url_helper.py[DEBUG]: [0/6] open 'http://169.254.169.254/2009-04-04/meta-data/public-keys/' with {'url': 'http://169.254.169.254/2009-04-04/meta-data/public-keys/', 'headers': {'User-Agent': 'Cloud-Init/0.7.9'}, 'allow_redirects': True, 'method': 'GET', 'timeout': 5.0} configuration
2019-02-16 13:19:11,121 - url_helper.py[DEBUG]: Read from http://169.254.169.254/2009-04-04/meta-data/public-keys/ (200, 7b) after 1 attempts
2019-02-16 13:19:11,121 - url_helper.py[DEBUG]: [0/6] open 'http://169.254.169.254/2009-04-04/meta-data/public-keys/0/openssh-key' with {'url': 'http://169.254.169.254/2009-04-04/meta-data/public-keys/0/openssh-key', 'headers': {'User-Agent': 'Cloud-Init/0.7.9'}, 'allow_redirects': True, 'method': 'GET', 'timeout': 5.0} configuration
2019-02-16 13:19:11,123 - url_helper.py[DEBUG]: Read from http://169.254.169.254/2009-04-04/meta-data/public-keys/0/openssh-key (200, 387b) after 1 attempts
2019-02-16 13:19:11,123 - url_helper.py[DEBUG]: [0/6] open 'http://169.254.169.254/2009-04-04/meta-data/profile' with {'url': 'http://169.254.169.254/2009-04-04/meta-data/profile', 'headers': {'User-Agent': 'Cloud-Init/0.7.9'}, 'allow_redirects': True, 'method': 'GET', 'timeout': 5.0} configuration
2019-02-16 13:19:11,125 - url_helper.py[DEBUG]: Read from http://169.254.169.254/2009-04-04/meta-data/profile (200, 11b) after 1 attempts
2019-02-16 13:19:11,125 - url_helper.py[DEBUG]: [0/6] open 'http://169.254.169.254/2009-04-04/meta-data/local-ipv4' with {'url': 'http://169.254.169.254/2009-04-04/meta-data/local-ipv4', 'headers': {'User-Agent': 'Cloud-Init/0.7.9'}, 'allow_redirects': True, 'method': 'GET', 'timeout': 5.0} configuration
2019-02-16 13:19:11,127 - url_helper.py[DEBUG]: Read from http://169.254.169.254/2009-04-04/meta-data/local-ipv4 (200, 12b) after 1 attempts
2019-02-16 13:19:11,127 - url_helper.py[DEBUG]: [0/6] open 'http://169.254.169.254/2009-04-04/meta-data/reservation-id' with {'url': 'http://169.254.169.254/2009-04-04/meta-data/reservation-id', 'headers': {'User-Agent': 'Cloud-Init/0.7.9'}, 'allow_redirects': True, 'method': 'GET', 'timeout': 5.0} configuration
2019-02-16 13:19:11,129 - url_helper.py[DEBUG]: Read from http://169.254.169.254/2009-04-04/meta-data/reservation-id (200, 19b) after 1 attempts
2019-02-16 13:19:11,129 - url_helper.py[DEBUG]: [0/6] open 'http://169.254.169.254/2009-04-04/meta-data/local-hostname' with {'url': 'http://169.254.169.254/2009-04-04/meta-data/local-hostname', 'headers': {'User-Agent': 'Cloud-Init/0.7.9'}, 'allow_redirects': True, 'method': 'GET', 'timeout': 5.0} configuration
2019-02-16 13:19:11,131 - url_helper.py[DEBUG]: Read from http://169.254.169.254/2009-04-04/meta-data/local-hostname (200, 42b) after 1 attempts
2019-02-16 13:19:11,131 - url_helper.py[DEBUG]: [0/6] open 'http://169.254.169.254/2009-04-04/meta-data/security-groups' with {'url': 'http://169.254.169.254/2009-04-04/meta-data/security-groups', 'headers': {'User-Agent': 'Cloud-Init/0.7.9'}, 'allow_redirects': True, 'method': 'GET', 'timeout': 5.0} configuration
2019-02-16 13:19:11,133 - url_helper.py[DEBUG]: Read from http://169.254.169.254/2009-04-04/meta-data/security-groups (200, 86b) after 1 attempts
2019-02-16 13:19:11,133 - url_helper.py[DEBUG]: [0/6] open 'http://169.254.169.254/2009-04-04/meta-data/ami-launch-index' with {'url': 'http://169.254.169.254/2009-04-04/meta-data/ami-launch-index', 'headers': {'User-Agent': 'Cloud-Init/0.7.9'}, 'allow_redirects': True, 'method': 'GET', 'timeout': 5.0} configuration
2019-02-16 13:19:11,135 - url_helper.py[DEBUG]: Read from http://169.254.169.254/2009-04-04/meta-data/ami-launch-index (200, 1b) after 1 attempts
2019-02-16 13:19:11,135 - url_helper.py[DEBUG]: [0/6] open 'http://169.254.169.254/2009-04-04/meta-data/public-hostname' with {'url': 'http://169.254.169.254/2009-04-04/meta-data/public-hostname', 'headers': {'User-Agent': 'Cloud-Init/0.7.9'}, 'allow_redirects': True, 'method': 'GET', 'timeout': 5.0} configuration
2019-02-16 13:19:11,137 - url_helper.py[DEBUG]: Read from http://169.254.169.254/2009-04-04/meta-data/public-hostname (200, 48b) after 1 attempts
2019-02-16 13:19:11,137 - url_helper.py[DEBUG]: [0/6] open 'http://169.254.169.254/2009-04-04/meta-data/hostname' with {'url': 'http://169.254.169.254/2009-04-04/meta-data/hostname', 'headers': {'User-Agent': 'Cloud-Init/0.7.9'}, 'allow_redirects': True, 'method': 'GET', 'timeout': 5.0} configuration
2019-02-16 13:19:11,139 - url_helper.py[DEBUG]: Read from http://169.254.169.254/2009-04-04/meta-data/hostname (200, 42b) after 1 attempts
2019-02-16 13:19:11,139 - url_helper.py[DEBUG]: [0/6] open 'http://169.254.169.254/2009-04-04/meta-data/ami-id' with {'url': 'http://169.254.169.254/2009-04-04/meta-data/ami-id', 'headers': {'User-Agent': 'Cloud-Init/0.7.9'}, 'allow_redirects': True, 'method': 'GET', 'timeout': 5.0} configuration
2019-02-16 13:19:11,141 - url_helper.py[DEBUG]: Read from http://169.254.169.254/2009-04-04/meta-data/ami-id (200, 12b) after 1 attempts
2019-02-16 13:19:11,141 - url_helper.py[DEBUG]: [0/6] open 'http://169.254.169.254/2009-04-04/meta-data/instance-action' with {'url': 'http://169.254.169.254/2009-04-04/meta-data/instance-action', 'headers': {'User-Agent': 'Cloud-Init/0.7.9'}, 'allow_redirects': True, 'method': 'GET', 'timeout': 5.0} configuration
2019-02-16 13:19:11,143 - url_helper.py[DEBUG]: Read from http://169.254.169.254/2009-04-04/meta-data/instance-action (200, 4b) after 1 attempts
2019-02-16 13:19:11,143 - url_helper.py[DEBUG]: [0/6] open 'http://169.254.169.254/2009-04-04/meta-data/public-ipv4' with {'url': 'http://169.254.169.254/2009-04-04/meta-data/public-ipv4', 'headers': {'User-Agent': 'Cloud-Init/0.7.9'}, 'allow_redirects': True, 'method': 'GET', 'timeout': 5.0} configuration
2019-02-16 13:19:11,145 - url_helper.py[DEBUG]: Read from http://169.254.169.254/2009-04-04/meta-data/public-ipv4 (200, 12b) after 1 attempts
2019-02-16 13:19:11,145 - url_helper.py[DEBUG]: [0/6] open 'http://169.254.169.254/2009-04-04/meta-data/ami-manifest-path' with {'url': 'http://169.254.169.254/2009-04-04/meta-data/ami-manifest-path', 'headers': {'User-Agent': 'Cloud-Init/0.7.9'}, 'allow_redirects': True, 'method': 'GET', 'timeout': 5.0} configuration
2019-02-16 13:19:11,147 - url_helper.py[DEBUG]: Read from http://169.254.169.254/2009-04-04/meta-data/ami-manifest-path (200, 9b) after 1 attempts
2019-02-16 13:19:11,147 - url_helper.py[DEBUG]: [0/6] open 'http://169.254.169.254/2009-04-04/meta-data/instance-type' with {'url': 'http://169.254.169.254/2009-04-04/meta-data/instance-type', 'headers': {'User-Agent': 'Cloud-Init/0.7.9'}, 'allow_redirects': True, 'method': 'GET', 'timeout': 5.0} configuration
2019-02-16 13:19:11,149 - url_helper.py[DEBUG]: Read from http://169.254.169.254/2009-04-04/meta-data/instance-type (200, 9b) after 1 attempts
2019-02-16 13:19:11,149 - url_helper.py[DEBUG]: [0/6] open 'http://169.254.169.254/2009-04-04/meta-data/instance-id' with {'url': 'http://169.254.169.254/2009-04-04/meta-data/instance-id', 'headers': {'User-Agent': 'Cloud-Init/0.7.9'}, 'allow_redirects': True, 'method': 'GET', 'timeout': 5.0} configuration
2019-02-16 13:19:11,151 - url_helper.py[DEBUG]: Read from http://169.254.169.254/2009-04-04/meta-data/instance-id (200, 19b) after 1 attempts
2019-02-16 13:19:11,151 - DataSourceEc2.py[DEBUG]: Crawl of metadata service took 0.046 seconds
2019-02-16 13:19:11,151 - handlers.py[DEBUG]: finish: init-network/search-Ec2: SUCCESS: found network data from DataSourceEc2
2019-02-16 13:19:11,151 - stages.py[INFO]: Loaded datasource DataSourceEc2 - DataSourceEc2
2019-02-16 13:19:11,151 - util.py[DEBUG]: Reading from /etc/cloud/cloud.cfg (quiet=False)
2019-02-16 13:19:11,152 - util.py[DEBUG]: Read 1148 bytes from /etc/cloud/cloud.cfg
2019-02-16 13:19:11,152 - util.py[DEBUG]: Attempting to load yaml from string of length 1148 with allowed root types (<type 'dict'>,)
2019-02-16 13:19:11,160 - util.py[DEBUG]: Reading from /etc/cloud/cloud.cfg.d/05_logging.cfg (quiet=False)
2019-02-16 13:19:11,160 - util.py[DEBUG]: Read 1821 bytes from /etc/cloud/cloud.cfg.d/05_logging.cfg
2019-02-16 13:19:11,160 - util.py[DEBUG]: Attempting to load yaml from string of length 1821 with allowed root types (<type 'dict'>,)
2019-02-16 13:19:11,163 - util.py[DEBUG]: Attempting to load yaml from string of length 0 with allowed root types (<type 'dict'>,)
2019-02-16 13:19:11,164 - util.py[DEBUG]: load_yaml given empty string, returning default
2019-02-16 13:19:11,164 - util.py[DEBUG]: Attempting to remove /var/lib/cloud/instance
2019-02-16 13:19:11,164 - util.py[DEBUG]: Creating symbolic link from '/var/lib/cloud/instance' => '/var/lib/cloud/instances/i-0d734ede44d97ba0b'
2019-02-16 13:19:11,165 - util.py[DEBUG]: Restoring selinux mode for /var/lib/cloud/instances/i-0d734ede44d97ba0b (recursive=True)
2019-02-16 13:19:11,166 - util.py[DEBUG]: Restoring selinux mode for /var/lib/cloud/instances/i-0d734ede44d97ba0b/handlers (recursive=False)
2019-02-16 13:19:11,166 - util.py[DEBUG]: Restoring selinux mode for /var/lib/cloud/instances/i-0d734ede44d97ba0b (recursive=True)
2019-02-16 13:19:11,167 - util.py[DEBUG]: Restoring selinux mode for /var/lib/cloud/instances/i-0d734ede44d97ba0b/scripts (recursive=False)
2019-02-16 13:19:11,167 - util.py[DEBUG]: Restoring selinux mode for /var/lib/cloud/instances/i-0d734ede44d97ba0b (recursive=True)
2019-02-16 13:19:11,168 - util.py[DEBUG]: Restoring selinux mode for /var/lib/cloud/instances/i-0d734ede44d97ba0b/sem (recursive=False)
2019-02-16 13:19:11,169 - util.py[DEBUG]: Reading from /var/lib/cloud/instances/i-0d734ede44d97ba0b/datasource (quiet=False)
2019-02-16 13:19:11,169 - util.py[DEBUG]: Writing to /var/lib/cloud/instances/i-0d734ede44d97ba0b/datasource - wb: [420] 29 bytes
2019-02-16 13:19:11,169 - util.py[DEBUG]: Restoring selinux mode for /var/lib/cloud/instances/i-0d734ede44d97ba0b/datasource (recursive=False)
2019-02-16 13:19:11,170 - util.py[DEBUG]: Restoring selinux mode for /var/lib/cloud/instances/i-0d734ede44d97ba0b/datasource (recursive=False)
2019-02-16 13:19:11,170 - util.py[DEBUG]: Writing to /var/lib/cloud/data/previous-datasource - wb: [420] 29 bytes
2019-02-16 13:19:11,170 - util.py[DEBUG]: Restoring selinux mode for /var/lib/cloud/data/previous-datasource (recursive=False)
2019-02-16 13:19:11,171 - util.py[DEBUG]: Restoring selinux mode for /var/lib/cloud/data/previous-datasource (recursive=False)
2019-02-16 13:19:11,171 - util.py[DEBUG]: Reading from /var/lib/cloud/data/instance-id (quiet=False)
2019-02-16 13:19:11,171 - stages.py[DEBUG]: previous iid found to be NO_PREVIOUS_INSTANCE_ID
2019-02-16 13:19:11,171 - util.py[DEBUG]: Writing to /var/lib/cloud/data/instance-id - wb: [420] 20 bytes
2019-02-16 13:19:11,172 - util.py[DEBUG]: Restoring selinux mode for /var/lib/cloud/data/instance-id (recursive=False)
2019-02-16 13:19:11,172 - util.py[DEBUG]: Restoring selinux mode for /var/lib/cloud/data/instance-id (recursive=False)
2019-02-16 13:19:11,172 - util.py[DEBUG]: Writing to /run/cloud-init/.instance-id - wb: [420] 20 bytes
2019-02-16 13:19:11,173 - util.py[DEBUG]: Restoring selinux mode for /run/cloud-init/.instance-id (recursive=False)
2019-02-16 13:19:11,174 - util.py[DEBUG]: Restoring selinux mode for /run/cloud-init/.instance-id (recursive=False)
2019-02-16 13:19:11,174 - util.py[DEBUG]: Writing to /var/lib/cloud/data/previous-instance-id - wb: [420] 24 bytes
2019-02-16 13:19:11,174 - util.py[DEBUG]: Restoring selinux mode for /var/lib/cloud/data/previous-instance-id (recursive=False)
2019-02-16 13:19:11,175 - util.py[DEBUG]: Restoring selinux mode for /var/lib/cloud/data/previous-instance-id (recursive=False)
2019-02-16 13:19:11,176 - util.py[DEBUG]: Writing to /var/lib/cloud/instance/obj.pkl - wb: [256] 9166 bytes
2019-02-16 13:19:11,176 - util.py[DEBUG]: Restoring selinux mode for /var/lib/cloud/instances/i-0d734ede44d97ba0b/obj.pkl (recursive=False)
2019-02-16 13:19:11,177 - util.py[DEBUG]: Restoring selinux mode for /var/lib/cloud/instances/i-0d734ede44d97ba0b/obj.pkl (recursive=False)
2019-02-16 13:19:11,177 - main.py[DEBUG]: [net] init will now be targeting instance id: i-0d734ede44d97ba0b. new=True
2019-02-16 13:19:11,177 - util.py[DEBUG]: Reading from /etc/cloud/cloud.cfg (quiet=False)
2019-02-16 13:19:11,177 - util.py[DEBUG]: Read 1148 bytes from /etc/cloud/cloud.cfg
2019-02-16 13:19:11,177 - util.py[DEBUG]: Attempting to load yaml from string of length 1148 with allowed root types (<type 'dict'>,)
2019-02-16 13:19:11,185 - util.py[DEBUG]: Reading from /etc/cloud/cloud.cfg.d/05_logging.cfg (quiet=False)
2019-02-16 13:19:11,185 - util.py[DEBUG]: Read 1821 bytes from /etc/cloud/cloud.cfg.d/05_logging.cfg
2019-02-16 13:19:11,185 - util.py[DEBUG]: Attempting to load yaml from string of length 1821 with allowed root types (<type 'dict'>,)
2019-02-16 13:19:11,189 - util.py[DEBUG]: Attempting to load yaml from string of length 0 with allowed root types (<type 'dict'>,)
2019-02-16 13:19:11,189 - util.py[DEBUG]: load_yaml given empty string, returning default
2019-02-16 13:19:11,190 - util.py[DEBUG]: Reading from /sys/class/net/eth0/carrier (quiet=False)
2019-02-16 13:19:11,190 - util.py[DEBUG]: Read 2 bytes from /sys/class/net/eth0/carrier
2019-02-16 13:19:11,190 - util.py[DEBUG]: Reading from /sys/class/net/eth0/address (quiet=False)
2019-02-16 13:19:11,190 - util.py[DEBUG]: Read 18 bytes from /sys/class/net/eth0/address
2019-02-16 13:19:11,190 - stages.py[DEBUG]: applying net config names for {'version': 1, 'config': [{'subnets': [{'type': 'dhcp'}], 'type': 'physical', 'name': 'eth0', 'mac_address': '02:a3:bc:dc:d6:e6'}]}
2019-02-16 13:19:11,191 - stages.py[DEBUG]: Using distro class <class 'cloudinit.distros.rhel.Distro'>
2019-02-16 13:19:11,191 - util.py[DEBUG]: Reading from /sys/class/net/lo/addr_assign_type (quiet=False)
2019-02-16 13:19:11,191 - util.py[DEBUG]: Read 2 bytes from /sys/class/net/lo/addr_assign_type
2019-02-16 13:19:11,191 - util.py[DEBUG]: Reading from /sys/class/net/lo/address (quiet=False)
2019-02-16 13:19:11,191 - util.py[DEBUG]: Read 18 bytes from /sys/class/net/lo/address
2019-02-16 13:19:11,191 - util.py[DEBUG]: Reading from /sys/class/net/eth0/addr_assign_type (quiet=False)
2019-02-16 13:19:11,191 - util.py[DEBUG]: Read 2 bytes from /sys/class/net/eth0/addr_assign_type
2019-02-16 13:19:11,192 - util.py[DEBUG]: Reading from /sys/class/net/eth0/address (quiet=False)
2019-02-16 13:19:11,192 - util.py[DEBUG]: Read 18 bytes from /sys/class/net/eth0/address
2019-02-16 13:19:11,192 - util.py[DEBUG]: Reading from /sys/class/net/eth0/operstate (quiet=False)
2019-02-16 13:19:11,192 - util.py[DEBUG]: Read 3 bytes from /sys/class/net/eth0/operstate
2019-02-16 13:19:11,192 - util.py[DEBUG]: Reading from /sys/class/net/lo/operstate (quiet=False)
2019-02-16 13:19:11,192 - util.py[DEBUG]: Read 8 bytes from /sys/class/net/lo/operstate
2019-02-16 13:19:11,192 - util.py[DEBUG]: Running command ['ip', '-6', 'addr', 'show', 'permanent', 'scope', 'global'] with allowed return codes [0] (shell=False, capture=True)
2019-02-16 13:19:11,198 - util.py[DEBUG]: Running command ['ip', '-4', 'addr', 'show'] with allowed return codes [0] (shell=False, capture=True)
2019-02-16 13:19:11,201 - __init__.py[DEBUG]: no work necessary for renaming of [['02:a3:bc:dc:d6:e6', 'eth0']]
2019-02-16 13:19:11,201 - stages.py[INFO]: Applying network configuration from fallback bringup=True: {'version': 1, 'config': [{'subnets': [{'type': 'dhcp'}], 'type': 'physical', 'name': 'eth0', 'mac_address': '02:a3:bc:dc:d6:e6'}]}
2019-02-16 13:19:11,204 - util.py[DEBUG]: Writing to /etc/sysconfig/network-scripts/ifcfg-eth0 - wb: [420] 159 bytes
2019-02-16 13:19:11,204 - util.py[DEBUG]: Restoring selinux mode for /etc/sysconfig/network-scripts/ifcfg-eth0 (recursive=False)
2019-02-16 13:19:11,205 - util.py[DEBUG]: Restoring selinux mode for /etc/sysconfig/network-scripts/ifcfg-eth0 (recursive=False)
2019-02-16 13:19:11,205 - util.py[DEBUG]: Reading from /etc/resolv.conf (quiet=False)
2019-02-16 13:19:11,205 - util.py[DEBUG]: Read 84 bytes from /etc/resolv.conf
2019-02-16 13:19:11,205 - util.py[DEBUG]: Writing to /etc/resolv.conf - wb: [420] 155 bytes
2019-02-16 13:19:11,205 - util.py[DEBUG]: Restoring selinux mode for /etc/resolv.conf (recursive=False)
2019-02-16 13:19:11,206 - util.py[DEBUG]: Restoring selinux mode for /etc/resolv.conf (recursive=False)
2019-02-16 13:19:11,206 - util.py[DEBUG]: Writing to /etc/udev/rules.d/70-persistent-net.rules - wb: [420] 96 bytes
2019-02-16 13:19:11,207 - util.py[DEBUG]: Restoring selinux mode for /etc/udev/rules.d/70-persistent-net.rules (recursive=False)
2019-02-16 13:19:11,207 - util.py[DEBUG]: Restoring selinux mode for /etc/udev/rules.d/70-persistent-net.rules (recursive=False)
2019-02-16 13:19:11,207 - util.py[DEBUG]: Writing to /var/lib/cloud/instances/i-0d734ede44d97ba0b/user-data.txt - wb: [384] 2734 bytes
2019-02-16 13:19:11,208 - util.py[DEBUG]: Restoring selinux mode for /var/lib/cloud/instances/i-0d734ede44d97ba0b/user-data.txt (recursive=False)
2019-02-16 13:19:11,208 - util.py[DEBUG]: Restoring selinux mode for /var/lib/cloud/instances/i-0d734ede44d97ba0b/user-data.txt (recursive=False)
2019-02-16 13:19:11,212 - util.py[DEBUG]: Writing to /var/lib/cloud/instances/i-0d734ede44d97ba0b/user-data.txt.i - wb: [384] 3076 bytes
2019-02-16 13:19:11,212 - util.py[DEBUG]: Restoring selinux mode for /var/lib/cloud/instances/i-0d734ede44d97ba0b/user-data.txt.i (recursive=False)
2019-02-16 13:19:11,213 - util.py[DEBUG]: Restoring selinux mode for /var/lib/cloud/instances/i-0d734ede44d97ba0b/user-data.txt.i (recursive=False)
2019-02-16 13:19:11,213 - util.py[DEBUG]: Writing to /var/lib/cloud/instances/i-0d734ede44d97ba0b/vendor-data.txt - wb: [384] 0 bytes
2019-02-16 13:19:11,213 - util.py[DEBUG]: Restoring selinux mode for /var/lib/cloud/instances/i-0d734ede44d97ba0b/vendor-data.txt (recursive=False)
2019-02-16 13:19:11,214 - util.py[DEBUG]: Restoring selinux mode for /var/lib/cloud/instances/i-0d734ede44d97ba0b/vendor-data.txt (recursive=False)
2019-02-16 13:19:11,215 - util.py[DEBUG]: Writing to /var/lib/cloud/instances/i-0d734ede44d97ba0b/vendor-data.txt.i - wb: [384] 344 bytes
2019-02-16 13:19:11,215 - util.py[DEBUG]: Restoring selinux mode for /var/lib/cloud/instances/i-0d734ede44d97ba0b/vendor-data.txt.i (recursive=False)
2019-02-16 13:19:11,216 - util.py[DEBUG]: Restoring selinux mode for /var/lib/cloud/instances/i-0d734ede44d97ba0b/vendor-data.txt.i (recursive=False)
2019-02-16 13:19:11,216 - util.py[DEBUG]: Writing to /var/lib/cloud/instances/i-0d734ede44d97ba0b/sem/consume_data - wb: [420] 19 bytes
2019-02-16 13:19:11,217 - util.py[DEBUG]: Restoring selinux mode for /var/lib/cloud/instances/i-0d734ede44d97ba0b/sem/consume_data (recursive=False)
2019-02-16 13:19:11,217 - util.py[DEBUG]: Restoring selinux mode for /var/lib/cloud/instances/i-0d734ede44d97ba0b/sem/consume_data (recursive=False)
2019-02-16 13:19:11,218 - helpers.py[DEBUG]: Running consume_data using lock (<FileLock using file '/var/lib/cloud/instances/i-0d734ede44d97ba0b/sem/consume_data'>)
2019-02-16 13:19:11,218 - handlers.py[DEBUG]: start: init-network/consume-user-data: reading and applying user-data
2019-02-16 13:19:11,218 - launch_index.py[DEBUG]: Discarding 0 multipart messages which do not match launch index 0
2019-02-16 13:19:11,218 - stages.py[DEBUG]: Added default handler for set(['text/cloud-config-jsonp', 'text/cloud-config']) from CloudConfigPartHandler: [['text/cloud-config', 'text/cloud-config-jsonp']]
2019-02-16 13:19:11,219 - stages.py[DEBUG]: Added default handler for set(['text/x-shellscript']) from ShellScriptPartHandler: [['text/x-shellscript']]
2019-02-16 13:19:11,219 - stages.py[DEBUG]: Added default handler for set(['text/cloud-boothook']) from BootHookPartHandler: [['text/cloud-boothook']]
2019-02-16 13:19:11,219 - stages.py[DEBUG]: Added default handler for set(['text/upstart-job']) from UpstartJobPartHandler: [['text/upstart-job']]
2019-02-16 13:19:11,219 - __init__.py[DEBUG]: Calling handler BootHookPartHandler: [['text/cloud-boothook']] (__begin__, None, 2) with frequency once-per-instance
2019-02-16 13:19:11,219 - __init__.py[DEBUG]: Calling handler UpstartJobPartHandler: [['text/upstart-job']] (__begin__, None, 2) with frequency once-per-instance
2019-02-16 13:19:11,219 - __init__.py[DEBUG]: Calling handler CloudConfigPartHandler: [['text/cloud-config', 'text/cloud-config-jsonp']] (__begin__, None, 3) with frequency once-per-instance
2019-02-16 13:19:11,219 - __init__.py[DEBUG]: Calling handler ShellScriptPartHandler: [['text/x-shellscript']] (__begin__, None, 2) with frequency once-per-instance
2019-02-16 13:19:11,219 - __init__.py[DEBUG]: {'Content-Type': 'text/x-shellscript', 'Content-Disposition': 'attachment; filename="part-001"', 'MIME-Version': '1.0'}
2019-02-16 13:19:11,220 - __init__.py[DEBUG]: Calling handler ShellScriptPartHandler: [['text/x-shellscript']] (text/x-shellscript, part-001, 2) with frequency once-per-instance
2019-02-16 13:19:11,220 - util.py[DEBUG]: Writing to /var/lib/cloud/instance/scripts/part-001 - wb: [448] 2734 bytes
2019-02-16 13:19:11,220 - util.py[DEBUG]: Restoring selinux mode for /var/lib/cloud/instances/i-0d734ede44d97ba0b/scripts/part-001 (recursive=False)
2019-02-16 13:19:11,221 - util.py[DEBUG]: Restoring selinux mode for /var/lib/cloud/instances/i-0d734ede44d97ba0b/scripts/part-001 (recursive=False)
2019-02-16 13:19:11,221 - __init__.py[DEBUG]: Calling handler BootHookPartHandler: [['text/cloud-boothook']] (__end__, None, 2) with frequency once-per-instance
2019-02-16 13:19:11,221 - __init__.py[DEBUG]: Calling handler UpstartJobPartHandler: [['text/upstart-job']] (__end__, None, 2) with frequency once-per-instance
2019-02-16 13:19:11,221 - __init__.py[DEBUG]: Calling handler CloudConfigPartHandler: [['text/cloud-config', 'text/cloud-config-jsonp']] (__end__, None, 3) with frequency once-per-instance
2019-02-16 13:19:11,221 - util.py[DEBUG]: Writing to /var/lib/cloud/instances/i-0d734ede44d97ba0b/cloud-config.txt - wb: [384] 0 bytes
2019-02-16 13:19:11,222 - util.py[DEBUG]: Restoring selinux mode for /var/lib/cloud/instances/i-0d734ede44d97ba0b/cloud-config.txt (recursive=False)
2019-02-16 13:19:11,222 - util.py[DEBUG]: Restoring selinux mode for /var/lib/cloud/instances/i-0d734ede44d97ba0b/cloud-config.txt (recursive=False)
2019-02-16 13:19:11,222 - __init__.py[DEBUG]: Calling handler ShellScriptPartHandler: [['text/x-shellscript']] (__end__, None, 2) with frequency once-per-instance
2019-02-16 13:19:11,223 - handlers.py[DEBUG]: finish: init-network/consume-user-data: SUCCESS: reading and applying user-data
2019-02-16 13:19:11,223 - handlers.py[DEBUG]: start: init-network/consume-vendor-data: reading and applying vendor-data
2019-02-16 13:19:11,223 - stages.py[DEBUG]: no vendordata from datasource
2019-02-16 13:19:11,223 - handlers.py[DEBUG]: finish: init-network/consume-vendor-data: SUCCESS: reading and applying vendor-data
2019-02-16 13:19:11,223 - util.py[DEBUG]: Reading from /etc/cloud/cloud.cfg (quiet=False)
2019-02-16 13:19:11,223 - util.py[DEBUG]: Read 1148 bytes from /etc/cloud/cloud.cfg
2019-02-16 13:19:11,223 - util.py[DEBUG]: Attempting to load yaml from string of length 1148 with allowed root types (<type 'dict'>,)
2019-02-16 13:19:11,232 - util.py[DEBUG]: Reading from /etc/cloud/cloud.cfg.d/05_logging.cfg (quiet=False)
2019-02-16 13:19:11,232 - util.py[DEBUG]: Read 1821 bytes from /etc/cloud/cloud.cfg.d/05_logging.cfg
2019-02-16 13:19:11,232 - util.py[DEBUG]: Attempting to load yaml from string of length 1821 with allowed root types (<type 'dict'>,)
2019-02-16 13:19:11,235 - util.py[DEBUG]: Attempting to load yaml from string of length 0 with allowed root types (<type 'dict'>,)
2019-02-16 13:19:11,236 - util.py[DEBUG]: load_yaml given empty string, returning default
2019-02-16 13:19:11,236 - util.py[DEBUG]: Reading from /var/lib/cloud/instance/cloud-config.txt (quiet=False)
2019-02-16 13:19:11,236 - util.py[DEBUG]: Read 0 bytes from /var/lib/cloud/instance/cloud-config.txt
2019-02-16 13:19:11,236 - util.py[DEBUG]: Attempting to load yaml from string of length 0 with allowed root types (<type 'dict'>,)
2019-02-16 13:19:11,236 - util.py[DEBUG]: load_yaml given empty string, returning default
2019-02-16 13:19:11,237 - util.py[DEBUG]: Reading from /var/lib/cloud/instance/cloud-config.txt (quiet=False)
2019-02-16 13:19:11,237 - util.py[DEBUG]: Read 0 bytes from /var/lib/cloud/instance/cloud-config.txt
2019-02-16 13:19:11,237 - util.py[DEBUG]: Attempting to load yaml from string of length 0 with allowed root types (<type 'dict'>,)
2019-02-16 13:19:11,237 - util.py[DEBUG]: load_yaml given empty string, returning default
2019-02-16 13:19:11,240 - util.py[DEBUG]: Writing to /var/lib/cloud/instance/obj.pkl - wb: [256] 8189 bytes
2019-02-16 13:19:11,240 - util.py[DEBUG]: Restoring selinux mode for /var/lib/cloud/instances/i-0d734ede44d97ba0b/obj.pkl (recursive=False)
2019-02-16 13:19:11,241 - util.py[DEBUG]: Restoring selinux mode for /var/lib/cloud/instances/i-0d734ede44d97ba0b/obj.pkl (recursive=False)
2019-02-16 13:19:11,250 - stages.py[DEBUG]: Using distro class <class 'cloudinit.distros.rhel.Distro'>
2019-02-16 13:19:11,250 - stages.py[DEBUG]: Running module migrator (<module 'cloudinit.config.cc_migrator' from '/usr/lib/python2.7/site-packages/cloudinit/config/cc_migrator.pyc'>) with frequency always
2019-02-16 13:19:11,251 - handlers.py[DEBUG]: start: init-network/config-migrator: running config-migrator with frequency always
2019-02-16 13:19:11,251 - helpers.py[DEBUG]: Running config-migrator using lock (<cloudinit.helpers.DummyLock object at 0x7f70aff57590>)
2019-02-16 13:19:11,251 - cc_migrator.py[DEBUG]: Migrated 0 semaphore files to there canonicalized names
2019-02-16 13:19:11,251 - handlers.py[DEBUG]: finish: init-network/config-migrator: SUCCESS: config-migrator ran successfully
2019-02-16 13:19:11,251 - stages.py[DEBUG]: Running module bootcmd (<module 'cloudinit.config.cc_bootcmd' from '/usr/lib/python2.7/site-packages/cloudinit/config/cc_bootcmd.pyc'>) with frequency always
2019-02-16 13:19:11,251 - handlers.py[DEBUG]: start: init-network/config-bootcmd: running config-bootcmd with frequency always
2019-02-16 13:19:11,251 - helpers.py[DEBUG]: Running config-bootcmd using lock (<cloudinit.helpers.DummyLock object at 0x7f70aff57650>)
2019-02-16 13:19:11,251 - cc_bootcmd.py[DEBUG]: Skipping module named bootcmd, no 'bootcmd' key in configuration
2019-02-16 13:19:11,252 - handlers.py[DEBUG]: finish: init-network/config-bootcmd: SUCCESS: config-bootcmd ran successfully
2019-02-16 13:19:11,252 - stages.py[DEBUG]: Running module write-files (<module 'cloudinit.config.cc_write_files' from '/usr/lib/python2.7/site-packages/cloudinit/config/cc_write_files.pyc'>) with frequency once-per-instance
2019-02-16 13:19:11,252 - handlers.py[DEBUG]: start: init-network/config-write-files: running config-write-files with frequency once-per-instance
2019-02-16 13:19:11,252 - util.py[DEBUG]: Writing to /var/lib/cloud/instances/i-0d734ede44d97ba0b/sem/config_write_files - wb: [420] 19 bytes
2019-02-16 13:19:11,252 - util.py[DEBUG]: Restoring selinux mode for /var/lib/cloud/instances/i-0d734ede44d97ba0b/sem/config_write_files (recursive=False)
2019-02-16 13:19:11,253 - util.py[DEBUG]: Restoring selinux mode for /var/lib/cloud/instances/i-0d734ede44d97ba0b/sem/config_write_files (recursive=False)
2019-02-16 13:19:11,253 - helpers.py[DEBUG]: Running config-write-files using lock (<FileLock using file '/var/lib/cloud/instances/i-0d734ede44d97ba0b/sem/config_write_files'>)
2019-02-16 13:19:11,253 - cc_write_files.py[DEBUG]: Skipping module named write-files, no/empty 'write_files' key in configuration
2019-02-16 13:19:11,254 - handlers.py[DEBUG]: finish: init-network/config-write-files: SUCCESS: config-write-files ran successfully
2019-02-16 13:19:11,254 - stages.py[DEBUG]: Running module growpart (<module 'cloudinit.config.cc_growpart' from '/usr/lib/python2.7/site-packages/cloudinit/config/cc_growpart.pyc'>) with frequency always
2019-02-16 13:19:11,254 - handlers.py[DEBUG]: start: init-network/config-growpart: running config-growpart with frequency always
2019-02-16 13:19:11,254 - helpers.py[DEBUG]: Running config-growpart using lock (<cloudinit.helpers.DummyLock object at 0x7f70aff57750>)
2019-02-16 13:19:11,254 - cc_growpart.py[DEBUG]: No 'growpart' entry in cfg.  Using default: {'ignore_growroot_disabled': False, 'mode': 'auto', 'devices': ['/']}
2019-02-16 13:19:11,254 - util.py[DEBUG]: Running command ['growpart', '--help'] with allowed return codes [0] (shell=False, capture=True)
2019-02-16 13:19:11,262 - util.py[DEBUG]: Reading from /proc/833/mountinfo (quiet=False)
2019-02-16 13:19:11,263 - util.py[DEBUG]: Read 2774 bytes from /proc/833/mountinfo
2019-02-16 13:19:11,264 - util.py[DEBUG]: Reading from /sys/class/block/xvda2/partition (quiet=False)
2019-02-16 13:19:11,264 - util.py[DEBUG]: Read 2 bytes from /sys/class/block/xvda2/partition
2019-02-16 13:19:11,264 - util.py[DEBUG]: Reading from /sys/devices/vbd-768/block/xvda/dev (quiet=False)
2019-02-16 13:19:11,264 - util.py[DEBUG]: Read 6 bytes from /sys/devices/vbd-768/block/xvda/dev
2019-02-16 13:19:11,264 - util.py[DEBUG]: Running command ['growpart', '--dry-run', '/dev/xvda', '2'] with allowed return codes [0] (shell=False, capture=True)
2019-02-16 13:19:11,336 - util.py[DEBUG]: Running command ['growpart', '/dev/xvda', '2'] with allowed return codes [0] (shell=False, capture=True)
2019-02-16 13:19:12,439 - util.py[DEBUG]: resize_devices took 1.176 seconds
2019-02-16 13:19:12,439 - cc_growpart.py[INFO]: '/' resized: changed (/dev/xvda, 2) from 6442450944 to 10735304192
2019-02-16 13:19:12,439 - handlers.py[DEBUG]: finish: init-network/config-growpart: SUCCESS: config-growpart ran successfully
2019-02-16 13:19:12,439 - stages.py[DEBUG]: Running module resizefs (<module 'cloudinit.config.cc_resizefs' from '/usr/lib/python2.7/site-packages/cloudinit/config/cc_resizefs.pyc'>) with frequency always
2019-02-16 13:19:12,439 - handlers.py[DEBUG]: start: init-network/config-resizefs: running config-resizefs with frequency always
2019-02-16 13:19:12,440 - helpers.py[DEBUG]: Running config-resizefs using lock (<cloudinit.helpers.DummyLock object at 0x7f70aff57890>)
2019-02-16 13:19:12,440 - util.py[DEBUG]: Reading from /proc/833/mountinfo (quiet=False)
2019-02-16 13:19:12,441 - util.py[DEBUG]: Read 2774 bytes from /proc/833/mountinfo
2019-02-16 13:19:12,441 - cc_resizefs.py[DEBUG]: resize_info: dev=/dev/xvda2 mnt_point=/ path=/
2019-02-16 13:19:12,441 - util.py[DEBUG]: Running command ['systemd-detect-virt', '--quiet', '--container'] with allowed return codes [0] (shell=False, capture=True)
2019-02-16 13:19:12,445 - util.py[DEBUG]: Running command ['running-in-container'] with allowed return codes [0] (shell=False, capture=True)
2019-02-16 13:19:12,448 - util.py[DEBUG]: Running command ['lxc-is-container'] with allowed return codes [0] (shell=False, capture=True)
2019-02-16 13:19:12,452 - util.py[DEBUG]: Reading from /proc/1/environ (quiet=False)
2019-02-16 13:19:12,452 - util.py[DEBUG]: Read 0 bytes from /proc/1/environ
2019-02-16 13:19:12,452 - util.py[DEBUG]: Reading from /proc/self/status (quiet=False)
2019-02-16 13:19:12,452 - util.py[DEBUG]: Read 1150 bytes from /proc/self/status
2019-02-16 13:19:12,452 - cc_resizefs.py[DEBUG]: Resizing / (xfs) using xfs_growfs /dev/xvda2
2019-02-16 13:19:12,453 - util.py[DEBUG]: Running command ('xfs_growfs', '/dev/xvda2') with allowed return codes [0] (shell=False, capture=True)
2019-02-16 13:19:12,477 - util.py[DEBUG]: Resizing took 0.024 seconds
2019-02-16 13:19:12,477 - cc_resizefs.py[DEBUG]: Resized root filesystem (type=xfs, val=True)
2019-02-16 13:19:12,477 - handlers.py[DEBUG]: finish: init-network/config-resizefs: SUCCESS: config-resizefs ran successfully
2019-02-16 13:19:12,477 - stages.py[DEBUG]: Running module set_hostname (<module 'cloudinit.config.cc_set_hostname' from '/usr/lib/python2.7/site-packages/cloudinit/config/cc_set_hostname.pyc'>) with frequency once-per-instance
2019-02-16 13:19:12,478 - handlers.py[DEBUG]: start: init-network/config-set_hostname: running config-set_hostname with frequency once-per-instance
2019-02-16 13:19:12,478 - util.py[DEBUG]: Writing to /var/lib/cloud/instances/i-0d734ede44d97ba0b/sem/config_set_hostname - wb: [420] 19 bytes
2019-02-16 13:19:12,479 - util.py[DEBUG]: Restoring selinux mode for /var/lib/cloud/instances/i-0d734ede44d97ba0b/sem/config_set_hostname (recursive=False)
2019-02-16 13:19:12,480 - util.py[DEBUG]: Restoring selinux mode for /var/lib/cloud/instances/i-0d734ede44d97ba0b/sem/config_set_hostname (recursive=False)
2019-02-16 13:19:12,480 - helpers.py[DEBUG]: Running config-set_hostname using lock (<FileLock using file '/var/lib/cloud/instances/i-0d734ede44d97ba0b/sem/config_set_hostname'>)
2019-02-16 13:19:12,480 - cc_set_hostname.py[DEBUG]: Setting the hostname to ip-10-0-135-121.us-east-2.compute.internal (ip-10-0-135-121)
2019-02-16 13:19:12,480 - util.py[DEBUG]: Running command ['hostnamectl', 'set-hostname', 'ip-10-0-135-121.us-east-2.compute.internal'] with allowed return codes [0] (shell=False, capture=True)
2019-02-16 13:19:12,492 - __init__.py[DEBUG]: Non-persistently setting the system hostname to ip-10-0-135-121.us-east-2.compute.internal
2019-02-16 13:19:12,492 - util.py[DEBUG]: Running command ['hostname', 'ip-10-0-135-121.us-east-2.compute.internal'] with allowed return codes [0] (shell=False, capture=True)
2019-02-16 13:19:12,496 - handlers.py[DEBUG]: finish: init-network/config-set_hostname: SUCCESS: config-set_hostname ran successfully
2019-02-16 13:19:12,496 - stages.py[DEBUG]: Running module update_hostname (<module 'cloudinit.config.cc_update_hostname' from '/usr/lib/python2.7/site-packages/cloudinit/config/cc_update_hostname.pyc'>) with frequency always
2019-02-16 13:19:12,496 - handlers.py[DEBUG]: start: init-network/config-update_hostname: running config-update_hostname with frequency always
2019-02-16 13:19:12,497 - helpers.py[DEBUG]: Running config-update_hostname using lock (<cloudinit.helpers.DummyLock object at 0x7f70aff57e50>)
2019-02-16 13:19:12,497 - cc_update_hostname.py[DEBUG]: Updating hostname to ip-10-0-135-121.us-east-2.compute.internal (ip-10-0-135-121)
2019-02-16 13:19:12,497 - util.py[DEBUG]: Running command ['hostname'] with allowed return codes [0] (shell=False, capture=True)
2019-02-16 13:19:12,499 - __init__.py[DEBUG]: Attempting to update hostname to ip-10-0-135-121.us-east-2.compute.internal in 1 files
2019-02-16 13:19:12,500 - util.py[DEBUG]: Writing to /var/lib/cloud/data/previous-hostname - wb: [420] 42 bytes
2019-02-16 13:19:12,500 - util.py[DEBUG]: Restoring selinux mode for /var/lib/cloud/data/previous-hostname (recursive=False)
2019-02-16 13:19:12,501 - util.py[DEBUG]: Restoring selinux mode for /var/lib/cloud/data/previous-hostname (recursive=False)
2019-02-16 13:19:12,501 - handlers.py[DEBUG]: finish: init-network/config-update_hostname: SUCCESS: config-update_hostname ran successfully
2019-02-16 13:19:12,501 - stages.py[DEBUG]: Running module update_etc_hosts (<module 'cloudinit.config.cc_update_etc_hosts' from '/usr/lib/python2.7/site-packages/cloudinit/config/cc_update_etc_hosts.pyc'>) with frequency always
2019-02-16 13:19:12,502 - handlers.py[DEBUG]: start: init-network/config-update_etc_hosts: running config-update_etc_hosts with frequency always
2019-02-16 13:19:12,502 - helpers.py[DEBUG]: Running config-update_etc_hosts using lock (<cloudinit.helpers.DummyLock object at 0x7f70aff57f10>)
2019-02-16 13:19:12,502 - cc_update_etc_hosts.py[DEBUG]: Configuration option 'manage_etc_hosts' is not set, not managing /etc/hosts in module update_etc_hosts
2019-02-16 13:19:12,502 - handlers.py[DEBUG]: finish: init-network/config-update_etc_hosts: SUCCESS: config-update_etc_hosts ran successfully
2019-02-16 13:19:12,502 - stages.py[DEBUG]: Running module rsyslog (<module 'cloudinit.config.cc_rsyslog' from '/usr/lib/python2.7/site-packages/cloudinit/config/cc_rsyslog.pyc'>) with frequency once-per-instance
2019-02-16 13:19:12,502 - handlers.py[DEBUG]: start: init-network/config-rsyslog: running config-rsyslog with frequency once-per-instance
2019-02-16 13:19:12,502 - util.py[DEBUG]: Writing to /var/lib/cloud/instances/i-0d734ede44d97ba0b/sem/config_rsyslog - wb: [420] 18 bytes
2019-02-16 13:19:12,503 - util.py[DEBUG]: Restoring selinux mode for /var/lib/cloud/instances/i-0d734ede44d97ba0b/sem/config_rsyslog (recursive=False)
2019-02-16 13:19:12,503 - util.py[DEBUG]: Restoring selinux mode for /var/lib/cloud/instances/i-0d734ede44d97ba0b/sem/config_rsyslog (recursive=False)
2019-02-16 13:19:12,504 - helpers.py[DEBUG]: Running config-rsyslog using lock (<FileLock using file '/var/lib/cloud/instances/i-0d734ede44d97ba0b/sem/config_rsyslog'>)
2019-02-16 13:19:12,504 - cc_rsyslog.py[DEBUG]: Skipping module named rsyslog, no 'rsyslog' key in configuration
2019-02-16 13:19:12,504 - handlers.py[DEBUG]: finish: init-network/config-rsyslog: SUCCESS: config-rsyslog ran successfully
2019-02-16 13:19:12,504 - stages.py[DEBUG]: Running module users-groups (<module 'cloudinit.config.cc_users_groups' from '/usr/lib/python2.7/site-packages/cloudinit/config/cc_users_groups.pyc'>) with frequency once-per-instance
2019-02-16 13:19:12,504 - handlers.py[DEBUG]: start: init-network/config-users-groups: running config-users-groups with frequency once-per-instance
2019-02-16 13:19:12,504 - util.py[DEBUG]: Writing to /var/lib/cloud/instances/i-0d734ede44d97ba0b/sem/config_users_groups - wb: [420] 18 bytes
2019-02-16 13:19:12,505 - util.py[DEBUG]: Restoring selinux mode for /var/lib/cloud/instances/i-0d734ede44d97ba0b/sem/config_users_groups (recursive=False)
2019-02-16 13:19:12,505 - util.py[DEBUG]: Restoring selinux mode for /var/lib/cloud/instances/i-0d734ede44d97ba0b/sem/config_users_groups (recursive=False)
2019-02-16 13:19:12,506 - helpers.py[DEBUG]: Running config-users-groups using lock (<FileLock using file '/var/lib/cloud/instances/i-0d734ede44d97ba0b/sem/config_users_groups'>)
2019-02-16 13:19:12,506 - util.py[DEBUG]: Reading from /etc/system-image/channel.ini (quiet=True)
2019-02-16 13:19:12,506 - util.py[DEBUG]: Read 0 bytes from /etc/system-image/channel.ini
2019-02-16 13:19:12,507 - __init__.py[DEBUG]: Adding user ec2-user
2019-02-16 13:19:12,507 - util.py[DEBUG]: Running hidden command to protect sensitive input/output logstring: ['useradd', 'ec2-user', '--comment', 'Cloud User', '--groups', 'adm,systemd-journal,wheel', '--shell', '/bin/bash', '-m']
2019-02-16 13:19:12,545 - util.py[DEBUG]: Running command ['passwd', '-l', 'ec2-user'] with allowed return codes [0] (shell=False, capture=True)
2019-02-16 13:19:12,566 - util.py[DEBUG]: Reading from /etc/sudoers (quiet=False)
2019-02-16 13:19:12,566 - util.py[DEBUG]: Read 3971 bytes from /etc/sudoers
2019-02-16 13:19:12,567 - util.py[DEBUG]: Restoring selinux mode for /etc/sudoers.d (recursive=False)
2019-02-16 13:19:12,568 - util.py[DEBUG]: Writing to /etc/sudoers.d/90-cloud-init-users - wb: [288] 127 bytes
2019-02-16 13:19:12,568 - util.py[DEBUG]: Restoring selinux mode for /etc/sudoers.d/90-cloud-init-users (recursive=False)
2019-02-16 13:19:12,569 - util.py[DEBUG]: Restoring selinux mode for /etc/sudoers.d/90-cloud-init-users (recursive=False)
2019-02-16 13:19:12,569 - handlers.py[DEBUG]: finish: init-network/config-users-groups: SUCCESS: config-users-groups ran successfully
2019-02-16 13:19:12,569 - stages.py[DEBUG]: Running module ssh (<module 'cloudinit.config.cc_ssh' from '/usr/lib/python2.7/site-packages/cloudinit/config/cc_ssh.pyc'>) with frequency once-per-instance
2019-02-16 13:19:12,570 - handlers.py[DEBUG]: start: init-network/config-ssh: running config-ssh with frequency once-per-instance
2019-02-16 13:19:12,570 - util.py[DEBUG]: Writing to /var/lib/cloud/instances/i-0d734ede44d97ba0b/sem/config_ssh - wb: [420] 19 bytes
2019-02-16 13:19:12,570 - util.py[DEBUG]: Restoring selinux mode for /var/lib/cloud/instances/i-0d734ede44d97ba0b/sem/config_ssh (recursive=False)
2019-02-16 13:19:12,571 - util.py[DEBUG]: Restoring selinux mode for /var/lib/cloud/instances/i-0d734ede44d97ba0b/sem/config_ssh (recursive=False)
2019-02-16 13:19:12,571 - helpers.py[DEBUG]: Running config-ssh using lock (<FileLock using file '/var/lib/cloud/instances/i-0d734ede44d97ba0b/sem/config_ssh'>)
2019-02-16 13:19:12,572 - util.py[DEBUG]: Restoring selinux mode for /home/ec2-user (recursive=True)
2019-02-16 13:19:12,573 - util.py[DEBUG]: Restoring selinux mode for /home/ec2-user/.ssh (recursive=False)
2019-02-16 13:19:12,573 - util.py[DEBUG]: Changing the ownership of /home/ec2-user/.ssh to 1000:1000
2019-02-16 13:19:12,573 - util.py[DEBUG]: Reading from /etc/ssh/sshd_config (quiet=False)
2019-02-16 13:19:12,574 - util.py[DEBUG]: Read 3907 bytes from /etc/ssh/sshd_config
2019-02-16 13:19:12,575 - util.py[DEBUG]: Restoring selinux mode for /home/ec2-user/.ssh (recursive=True)
2019-02-16 13:19:12,575 - util.py[DEBUG]: Restoring selinux mode for /home/ec2-user/.ssh (recursive=False)
2019-02-16 13:19:12,575 - util.py[DEBUG]: Writing to /home/ec2-user/.ssh/authorized_keys - wb: [384] 387 bytes
2019-02-16 13:19:12,575 - util.py[DEBUG]: Restoring selinux mode for /home/ec2-user/.ssh/authorized_keys (recursive=False)
2019-02-16 13:19:12,576 - util.py[DEBUG]: Restoring selinux mode for /home/ec2-user/.ssh/authorized_keys (recursive=False)
2019-02-16 13:19:12,576 - util.py[DEBUG]: Changing the ownership of /home/ec2-user/.ssh/authorized_keys to 1000:1000
2019-02-16 13:19:12,576 - util.py[DEBUG]: Restoring selinux mode for /home/ec2-user/.ssh (recursive=True)
2019-02-16 13:19:12,578 - util.py[DEBUG]: Restoring selinux mode for /root (recursive=True)
2019-02-16 13:19:12,579 - util.py[DEBUG]: Restoring selinux mode for /root/.ssh (recursive=False)
2019-02-16 13:19:12,579 - util.py[DEBUG]: Changing the ownership of /root/.ssh to 0:0
2019-02-16 13:19:12,579 - util.py[DEBUG]: Reading from /etc/ssh/sshd_config (quiet=False)
2019-02-16 13:19:12,579 - util.py[DEBUG]: Read 3907 bytes from /etc/ssh/sshd_config
2019-02-16 13:19:12,580 - util.py[DEBUG]: Restoring selinux mode for /root/.ssh (recursive=True)
2019-02-16 13:19:12,580 - util.py[DEBUG]: Restoring selinux mode for /root/.ssh (recursive=False)
2019-02-16 13:19:12,580 - util.py[DEBUG]: Writing to /root/.ssh/authorized_keys - wb: [384] 544 bytes
2019-02-16 13:19:12,581 - util.py[DEBUG]: Restoring selinux mode for /root/.ssh/authorized_keys (recursive=False)
2019-02-16 13:19:12,581 - util.py[DEBUG]: Restoring selinux mode for /root/.ssh/authorized_keys (recursive=False)
2019-02-16 13:19:12,581 - util.py[DEBUG]: Changing the ownership of /root/.ssh/authorized_keys to 0:0
2019-02-16 13:19:12,581 - util.py[DEBUG]: Restoring selinux mode for /root/.ssh (recursive=True)
2019-02-16 13:19:12,581 - handlers.py[DEBUG]: finish: init-network/config-ssh: SUCCESS: config-ssh ran successfully
2019-02-16 13:19:12,581 - main.py[DEBUG]: Ran 11 modules with 0 failures
2019-02-16 13:19:12,582 - util.py[DEBUG]: Reading from /proc/uptime (quiet=False)
2019-02-16 13:19:12,582 - util.py[DEBUG]: Read 11 bytes from /proc/uptime
2019-02-16 13:19:12,582 - util.py[DEBUG]: cloud-init mode 'init' took 1.796 seconds (1.79)
2019-02-16 13:19:12,582 - handlers.py[DEBUG]: finish: init-network: SUCCESS: searching for network datasources
2019-02-16 13:19:13,019 - util.py[DEBUG]: Cloud-init v. 0.7.9 running 'modules:config' at Sat, 16 Feb 2019 13:19:12 +0000. Up 9.41 seconds.
2019-02-16 13:19:13,033 - stages.py[DEBUG]: Using distro class <class 'cloudinit.distros.rhel.Distro'>
2019-02-16 13:19:13,034 - stages.py[DEBUG]: Running module mounts (<module 'cloudinit.config.cc_mounts' from '/usr/lib/python2.7/site-packages/cloudinit/config/cc_mounts.pyc'>) with frequency once-per-instance
2019-02-16 13:19:13,034 - handlers.py[DEBUG]: start: modules-config/config-mounts: running config-mounts with frequency once-per-instance
2019-02-16 13:19:13,035 - util.py[DEBUG]: Writing to /var/lib/cloud/instances/i-0d734ede44d97ba0b/sem/config_mounts - wb: [420] 20 bytes
2019-02-16 13:19:13,036 - util.py[DEBUG]: Restoring selinux mode for /var/lib/cloud/instances/i-0d734ede44d97ba0b/sem/config_mounts (recursive=False)
2019-02-16 13:19:13,037 - util.py[DEBUG]: Restoring selinux mode for /var/lib/cloud/instances/i-0d734ede44d97ba0b/sem/config_mounts (recursive=False)
2019-02-16 13:19:13,037 - helpers.py[DEBUG]: Running config-mounts using lock (<FileLock using file '/var/lib/cloud/instances/i-0d734ede44d97ba0b/sem/config_mounts'>)
2019-02-16 13:19:13,038 - cc_mounts.py[DEBUG]: mounts configuration is []
2019-02-16 13:19:13,038 - cc_mounts.py[DEBUG]: Attempting to determine the real name of ephemeral0
2019-02-16 13:19:13,038 - DataSourceEc2.py[DEBUG]: Unable to convert ephemeral0 to a device
2019-02-16 13:19:13,038 - cc_mounts.py[DEBUG]: Ignoring nonexistant default named mount ephemeral0
2019-02-16 13:19:13,038 - cc_mounts.py[DEBUG]: Attempting to determine the real name of swap
2019-02-16 13:19:13,038 - DataSourceEc2.py[DEBUG]: Unable to convert swap to a device
2019-02-16 13:19:13,038 - cc_mounts.py[DEBUG]: Ignoring nonexistant default named mount swap
2019-02-16 13:19:13,038 - cc_mounts.py[DEBUG]: no need to setup swap
2019-02-16 13:19:13,038 - cc_mounts.py[DEBUG]: No modifications to fstab needed.
2019-02-16 13:19:13,038 - handlers.py[DEBUG]: finish: modules-config/config-mounts: SUCCESS: config-mounts ran successfully
2019-02-16 13:19:13,038 - stages.py[DEBUG]: Running module locale (<module 'cloudinit.config.cc_locale' from '/usr/lib/python2.7/site-packages/cloudinit/config/cc_locale.pyc'>) with frequency once-per-instance
2019-02-16 13:19:13,039 - handlers.py[DEBUG]: start: modules-config/config-locale: running config-locale with frequency once-per-instance
2019-02-16 13:19:13,039 - util.py[DEBUG]: Writing to /var/lib/cloud/instances/i-0d734ede44d97ba0b/sem/config_locale - wb: [420] 20 bytes
2019-02-16 13:19:13,039 - util.py[DEBUG]: Restoring selinux mode for /var/lib/cloud/instances/i-0d734ede44d97ba0b/sem/config_locale (recursive=False)
2019-02-16 13:19:13,040 - util.py[DEBUG]: Restoring selinux mode for /var/lib/cloud/instances/i-0d734ede44d97ba0b/sem/config_locale (recursive=False)
2019-02-16 13:19:13,040 - helpers.py[DEBUG]: Running config-locale using lock (<FileLock using file '/var/lib/cloud/instances/i-0d734ede44d97ba0b/sem/config_locale'>)
2019-02-16 13:19:13,040 - cc_locale.py[DEBUG]: Setting locale to en_US.UTF-8
2019-02-16 13:19:13,040 - util.py[DEBUG]: Reading from /etc/locale.conf (quiet=False)
2019-02-16 13:19:13,041 - util.py[DEBUG]: Read 19 bytes from /etc/locale.conf
2019-02-16 13:19:13,041 - util.py[DEBUG]: Writing to /etc/locale.conf - wb: [420] 17 bytes
2019-02-16 13:19:13,042 - util.py[DEBUG]: Restoring selinux mode for /etc/locale.conf (recursive=False)
2019-02-16 13:19:13,042 - util.py[DEBUG]: Restoring selinux mode for /etc/locale.conf (recursive=False)
2019-02-16 13:19:13,043 - handlers.py[DEBUG]: finish: modules-config/config-locale: SUCCESS: config-locale ran successfully
2019-02-16 13:19:13,043 - stages.py[DEBUG]: Running module set-passwords (<module 'cloudinit.config.cc_set_passwords' from '/usr/lib/python2.7/site-packages/cloudinit/config/cc_set_passwords.pyc'>) with frequency once-per-instance
2019-02-16 13:19:13,043 - handlers.py[DEBUG]: start: modules-config/config-set-passwords: running config-set-passwords with frequency once-per-instance
2019-02-16 13:19:13,043 - util.py[DEBUG]: Writing to /var/lib/cloud/instances/i-0d734ede44d97ba0b/sem/config_set_passwords - wb: [420] 20 bytes
2019-02-16 13:19:13,044 - util.py[DEBUG]: Restoring selinux mode for /var/lib/cloud/instances/i-0d734ede44d97ba0b/sem/config_set_passwords (recursive=False)
2019-02-16 13:19:13,045 - util.py[DEBUG]: Restoring selinux mode for /var/lib/cloud/instances/i-0d734ede44d97ba0b/sem/config_set_passwords (recursive=False)
2019-02-16 13:19:13,045 - helpers.py[DEBUG]: Running config-set-passwords using lock (<FileLock using file '/var/lib/cloud/instances/i-0d734ede44d97ba0b/sem/config_set_passwords'>)
2019-02-16 13:19:13,045 - util.py[DEBUG]: Reading from /etc/ssh/sshd_config (quiet=False)
2019-02-16 13:19:13,046 - util.py[DEBUG]: Read 3907 bytes from /etc/ssh/sshd_config
2019-02-16 13:19:13,046 - cc_set_passwords.py[DEBUG]: Replacing auth line 65 with no
2019-02-16 13:19:13,047 - util.py[DEBUG]: Writing to /etc/ssh/sshd_config - wb: [384] 3905 bytes
2019-02-16 13:19:13,047 - util.py[DEBUG]: Restoring selinux mode for /etc/ssh/sshd_config (recursive=False)
2019-02-16 13:19:13,048 - util.py[DEBUG]: Restoring selinux mode for /etc/ssh/sshd_config (recursive=False)
2019-02-16 13:19:13,048 - util.py[DEBUG]: Running command ['service', 'sshd', 'restart'] with allowed return codes [0] (shell=False, capture=True)
2019-02-16 13:19:13,157 - cc_set_passwords.py[DEBUG]: Restarted the ssh daemon
2019-02-16 13:19:13,158 - handlers.py[DEBUG]: finish: modules-config/config-set-passwords: SUCCESS: config-set-passwords ran successfully
2019-02-16 13:19:13,158 - stages.py[DEBUG]: Running module rh_subscription (<module 'cloudinit.config.cc_rh_subscription' from '/usr/lib/python2.7/site-packages/cloudinit/config/cc_rh_subscription.pyc'>) with frequency once-per-instance
2019-02-16 13:19:13,158 - handlers.py[DEBUG]: start: modules-config/config-rh_subscription: running config-rh_subscription with frequency once-per-instance
2019-02-16 13:19:13,159 - util.py[DEBUG]: Writing to /var/lib/cloud/instances/i-0d734ede44d97ba0b/sem/config_rh_subscription - wb: [420] 20 bytes
2019-02-16 13:19:13,160 - util.py[DEBUG]: Restoring selinux mode for /var/lib/cloud/instances/i-0d734ede44d97ba0b/sem/config_rh_subscription (recursive=False)
2019-02-16 13:19:13,160 - util.py[DEBUG]: Restoring selinux mode for /var/lib/cloud/instances/i-0d734ede44d97ba0b/sem/config_rh_subscription (recursive=False)
2019-02-16 13:19:13,161 - helpers.py[DEBUG]: Running config-rh_subscription using lock (<FileLock using file '/var/lib/cloud/instances/i-0d734ede44d97ba0b/sem/config_rh_subscription'>)
2019-02-16 13:19:13,161 - cc_rh_subscription.py[DEBUG]: rh_subscription: module not configured.
2019-02-16 13:19:13,161 - handlers.py[DEBUG]: finish: modules-config/config-rh_subscription: SUCCESS: config-rh_subscription ran successfully
2019-02-16 13:19:13,161 - stages.py[DEBUG]: Running module yum-add-repo (<module 'cloudinit.config.cc_yum_add_repo' from '/usr/lib/python2.7/site-packages/cloudinit/config/cc_yum_add_repo.pyc'>) with frequency once-per-instance
2019-02-16 13:19:13,161 - handlers.py[DEBUG]: start: modules-config/config-yum-add-repo: running config-yum-add-repo with frequency once-per-instance
2019-02-16 13:19:13,161 - util.py[DEBUG]: Writing to /var/lib/cloud/instances/i-0d734ede44d97ba0b/sem/config_yum_add_repo - wb: [420] 20 bytes
2019-02-16 13:19:13,162 - util.py[DEBUG]: Restoring selinux mode for /var/lib/cloud/instances/i-0d734ede44d97ba0b/sem/config_yum_add_repo (recursive=False)
2019-02-16 13:19:13,162 - util.py[DEBUG]: Restoring selinux mode for /var/lib/cloud/instances/i-0d734ede44d97ba0b/sem/config_yum_add_repo (recursive=False)
2019-02-16 13:19:13,163 - helpers.py[DEBUG]: Running config-yum-add-repo using lock (<FileLock using file '/var/lib/cloud/instances/i-0d734ede44d97ba0b/sem/config_yum_add_repo'>)
2019-02-16 13:19:13,163 - cc_yum_add_repo.py[DEBUG]: Skipping module named yum-add-repo, no 'yum_repos' configuration found
2019-02-16 13:19:13,163 - handlers.py[DEBUG]: finish: modules-config/config-yum-add-repo: SUCCESS: config-yum-add-repo ran successfully
2019-02-16 13:19:13,163 - stages.py[DEBUG]: Running module package-update-upgrade-install (<module 'cloudinit.config.cc_package_update_upgrade_install' from '/usr/lib/python2.7/site-packages/cloudinit/config/cc_package_update_upgrade_install.pyc'>) with frequency once-per-instance
2019-02-16 13:19:13,163 - handlers.py[DEBUG]: start: modules-config/config-package-update-upgrade-install: running config-package-update-upgrade-install with frequency once-per-instance
2019-02-16 13:19:13,163 - util.py[DEBUG]: Writing to /var/lib/cloud/instances/i-0d734ede44d97ba0b/sem/config_package_update_upgrade_install - wb: [420] 20 bytes
2019-02-16 13:19:13,164 - util.py[DEBUG]: Restoring selinux mode for /var/lib/cloud/instances/i-0d734ede44d97ba0b/sem/config_package_update_upgrade_install (recursive=False)
2019-02-16 13:19:13,164 - util.py[DEBUG]: Restoring selinux mode for /var/lib/cloud/instances/i-0d734ede44d97ba0b/sem/config_package_update_upgrade_install (recursive=False)
2019-02-16 13:19:13,165 - helpers.py[DEBUG]: Running config-package-update-upgrade-install using lock (<FileLock using file '/var/lib/cloud/instances/i-0d734ede44d97ba0b/sem/config_package_update_upgrade_install'>)
2019-02-16 13:19:13,165 - handlers.py[DEBUG]: finish: modules-config/config-package-update-upgrade-install: SUCCESS: config-package-update-upgrade-install ran successfully
2019-02-16 13:19:13,165 - stages.py[DEBUG]: Running module timezone (<module 'cloudinit.config.cc_timezone' from '/usr/lib/python2.7/site-packages/cloudinit/config/cc_timezone.pyc'>) with frequency once-per-instance
2019-02-16 13:19:13,165 - handlers.py[DEBUG]: start: modules-config/config-timezone: running config-timezone with frequency once-per-instance
2019-02-16 13:19:13,165 - util.py[DEBUG]: Writing to /var/lib/cloud/instances/i-0d734ede44d97ba0b/sem/config_timezone - wb: [420] 20 bytes
2019-02-16 13:19:13,166 - util.py[DEBUG]: Restoring selinux mode for /var/lib/cloud/instances/i-0d734ede44d97ba0b/sem/config_timezone (recursive=False)
2019-02-16 13:19:13,166 - util.py[DEBUG]: Restoring selinux mode for /var/lib/cloud/instances/i-0d734ede44d97ba0b/sem/config_timezone (recursive=False)
2019-02-16 13:19:13,167 - helpers.py[DEBUG]: Running config-timezone using lock (<FileLock using file '/var/lib/cloud/instances/i-0d734ede44d97ba0b/sem/config_timezone'>)
2019-02-16 13:19:13,167 - cc_timezone.py[DEBUG]: Skipping module named timezone, no 'timezone' specified
2019-02-16 13:19:13,167 - handlers.py[DEBUG]: finish: modules-config/config-timezone: SUCCESS: config-timezone ran successfully
2019-02-16 13:19:13,167 - stages.py[DEBUG]: Running module puppet (<module 'cloudinit.config.cc_puppet' from '/usr/lib/python2.7/site-packages/cloudinit/config/cc_puppet.pyc'>) with frequency once-per-instance
2019-02-16 13:19:13,167 - handlers.py[DEBUG]: start: modules-config/config-puppet: running config-puppet with frequency once-per-instance
2019-02-16 13:19:13,167 - util.py[DEBUG]: Writing to /var/lib/cloud/instances/i-0d734ede44d97ba0b/sem/config_puppet - wb: [420] 20 bytes
2019-02-16 13:19:13,168 - util.py[DEBUG]: Restoring selinux mode for /var/lib/cloud/instances/i-0d734ede44d97ba0b/sem/config_puppet (recursive=False)
2019-02-16 13:19:13,168 - util.py[DEBUG]: Restoring selinux mode for /var/lib/cloud/instances/i-0d734ede44d97ba0b/sem/config_puppet (recursive=False)
2019-02-16 13:19:13,169 - helpers.py[DEBUG]: Running config-puppet using lock (<FileLock using file '/var/lib/cloud/instances/i-0d734ede44d97ba0b/sem/config_puppet'>)
2019-02-16 13:19:13,169 - cc_puppet.py[DEBUG]: Skipping module named puppet, no 'puppet' configuration found
2019-02-16 13:19:13,169 - handlers.py[DEBUG]: finish: modules-config/config-puppet: SUCCESS: config-puppet ran successfully
2019-02-16 13:19:13,169 - stages.py[DEBUG]: Running module chef (<module 'cloudinit.config.cc_chef' from '/usr/lib/python2.7/site-packages/cloudinit/config/cc_chef.pyc'>) with frequency once-per-instance
2019-02-16 13:19:13,169 - handlers.py[DEBUG]: start: modules-config/config-chef: running config-chef with frequency once-per-instance
2019-02-16 13:19:13,169 - util.py[DEBUG]: Writing to /var/lib/cloud/instances/i-0d734ede44d97ba0b/sem/config_chef - wb: [420] 20 bytes
2019-02-16 13:19:13,170 - util.py[DEBUG]: Restoring selinux mode for /var/lib/cloud/instances/i-0d734ede44d97ba0b/sem/config_chef (recursive=False)
2019-02-16 13:19:13,171 - util.py[DEBUG]: Restoring selinux mode for /var/lib/cloud/instances/i-0d734ede44d97ba0b/sem/config_chef (recursive=False)
2019-02-16 13:19:13,171 - helpers.py[DEBUG]: Running config-chef using lock (<FileLock using file '/var/lib/cloud/instances/i-0d734ede44d97ba0b/sem/config_chef'>)
2019-02-16 13:19:13,171 - cc_chef.py[DEBUG]: Skipping module named chef, no 'chef' key in configuration
2019-02-16 13:19:13,171 - handlers.py[DEBUG]: finish: modules-config/config-chef: SUCCESS: config-chef ran successfully
2019-02-16 13:19:13,171 - stages.py[DEBUG]: Running module salt-minion (<module 'cloudinit.config.cc_salt_minion' from '/usr/lib/python2.7/site-packages/cloudinit/config/cc_salt_minion.pyc'>) with frequency once-per-instance
2019-02-16 13:19:13,171 - handlers.py[DEBUG]: start: modules-config/config-salt-minion: running config-salt-minion with frequency once-per-instance
2019-02-16 13:19:13,172 - util.py[DEBUG]: Writing to /var/lib/cloud/instances/i-0d734ede44d97ba0b/sem/config_salt_minion - wb: [420] 20 bytes
2019-02-16 13:19:13,172 - util.py[DEBUG]: Restoring selinux mode for /var/lib/cloud/instances/i-0d734ede44d97ba0b/sem/config_salt_minion (recursive=False)
2019-02-16 13:19:13,173 - util.py[DEBUG]: Restoring selinux mode for /var/lib/cloud/instances/i-0d734ede44d97ba0b/sem/config_salt_minion (recursive=False)
2019-02-16 13:19:13,173 - helpers.py[DEBUG]: Running config-salt-minion using lock (<FileLock using file '/var/lib/cloud/instances/i-0d734ede44d97ba0b/sem/config_salt_minion'>)
2019-02-16 13:19:13,173 - cc_salt_minion.py[DEBUG]: Skipping module named salt-minion, no 'salt_minion' key in configuration
2019-02-16 13:19:13,173 - handlers.py[DEBUG]: finish: modules-config/config-salt-minion: SUCCESS: config-salt-minion ran successfully
2019-02-16 13:19:13,173 - stages.py[DEBUG]: Running module mcollective (<module 'cloudinit.config.cc_mcollective' from '/usr/lib/python2.7/site-packages/cloudinit/config/cc_mcollective.pyc'>) with frequency once-per-instance
2019-02-16 13:19:13,173 - handlers.py[DEBUG]: start: modules-config/config-mcollective: running config-mcollective with frequency once-per-instance
2019-02-16 13:19:13,174 - util.py[DEBUG]: Writing to /var/lib/cloud/instances/i-0d734ede44d97ba0b/sem/config_mcollective - wb: [420] 20 bytes
2019-02-16 13:19:13,174 - util.py[DEBUG]: Restoring selinux mode for /var/lib/cloud/instances/i-0d734ede44d97ba0b/sem/config_mcollective (recursive=False)
2019-02-16 13:19:13,175 - util.py[DEBUG]: Restoring selinux mode for /var/lib/cloud/instances/i-0d734ede44d97ba0b/sem/config_mcollective (recursive=False)
2019-02-16 13:19:13,175 - helpers.py[DEBUG]: Running config-mcollective using lock (<FileLock using file '/var/lib/cloud/instances/i-0d734ede44d97ba0b/sem/config_mcollective'>)
2019-02-16 13:19:13,175 - cc_mcollective.py[DEBUG]: Skipping module named mcollective, no 'mcollective' key in configuration
2019-02-16 13:19:13,175 - handlers.py[DEBUG]: finish: modules-config/config-mcollective: SUCCESS: config-mcollective ran successfully
2019-02-16 13:19:13,175 - stages.py[DEBUG]: Running module disable-ec2-metadata (<module 'cloudinit.config.cc_disable_ec2_metadata' from '/usr/lib/python2.7/site-packages/cloudinit/config/cc_disable_ec2_metadata.pyc'>) with frequency always
2019-02-16 13:19:13,176 - handlers.py[DEBUG]: start: modules-config/config-disable-ec2-metadata: running config-disable-ec2-metadata with frequency always
2019-02-16 13:19:13,176 - helpers.py[DEBUG]: Running config-disable-ec2-metadata using lock (<cloudinit.helpers.DummyLock object at 0x7fd8074b9f50>)
2019-02-16 13:19:13,176 - cc_disable_ec2_metadata.py[DEBUG]: Skipping module named disable-ec2-metadata, disabling the ec2 route not enabled
2019-02-16 13:19:13,176 - handlers.py[DEBUG]: finish: modules-config/config-disable-ec2-metadata: SUCCESS: config-disable-ec2-metadata ran successfully
2019-02-16 13:19:13,176 - stages.py[DEBUG]: Running module runcmd (<module 'cloudinit.config.cc_runcmd' from '/usr/lib/python2.7/site-packages/cloudinit/config/cc_runcmd.pyc'>) with frequency once-per-instance
2019-02-16 13:19:13,176 - handlers.py[DEBUG]: start: modules-config/config-runcmd: running config-runcmd with frequency once-per-instance
2019-02-16 13:19:13,176 - util.py[DEBUG]: Writing to /var/lib/cloud/instances/i-0d734ede44d97ba0b/sem/config_runcmd - wb: [420] 20 bytes
2019-02-16 13:19:13,177 - util.py[DEBUG]: Restoring selinux mode for /var/lib/cloud/instances/i-0d734ede44d97ba0b/sem/config_runcmd (recursive=False)
2019-02-16 13:19:13,177 - util.py[DEBUG]: Restoring selinux mode for /var/lib/cloud/instances/i-0d734ede44d97ba0b/sem/config_runcmd (recursive=False)
2019-02-16 13:19:13,178 - helpers.py[DEBUG]: Running config-runcmd using lock (<FileLock using file '/var/lib/cloud/instances/i-0d734ede44d97ba0b/sem/config_runcmd'>)
2019-02-16 13:19:13,178 - cc_runcmd.py[DEBUG]: Skipping module named runcmd, no 'runcmd' key in configuration
2019-02-16 13:19:13,178 - handlers.py[DEBUG]: finish: modules-config/config-runcmd: SUCCESS: config-runcmd ran successfully
2019-02-16 13:19:13,178 - main.py[DEBUG]: Ran 13 modules with 0 failures
2019-02-16 13:19:13,179 - util.py[DEBUG]: Reading from /proc/uptime (quiet=False)
2019-02-16 13:19:13,179 - util.py[DEBUG]: Read 11 bytes from /proc/uptime
2019-02-16 13:19:13,179 - util.py[DEBUG]: cloud-init mode 'modules' took 0.269 seconds (0.27)
2019-02-16 13:19:13,179 - handlers.py[DEBUG]: finish: modules-config: SUCCESS: running modules for config
2019-02-16 13:19:13,449 - util.py[DEBUG]: Cloud-init v. 0.7.9 running 'modules:final' at Sat, 16 Feb 2019 13:19:13 +0000. Up 9.88 seconds.
2019-02-16 13:19:13,457 - stages.py[DEBUG]: Using distro class <class 'cloudinit.distros.rhel.Distro'>
2019-02-16 13:19:13,457 - stages.py[DEBUG]: Running module rightscale_userdata (<module 'cloudinit.config.cc_rightscale_userdata' from '/usr/lib/python2.7/site-packages/cloudinit/config/cc_rightscale_userdata.pyc'>) with frequency once-per-instance
2019-02-16 13:19:13,458 - handlers.py[DEBUG]: start: modules-final/config-rightscale_userdata: running config-rightscale_userdata with frequency once-per-instance
2019-02-16 13:19:13,458 - util.py[DEBUG]: Writing to /var/lib/cloud/instances/i-0d734ede44d97ba0b/sem/config_rightscale_userdata - wb: [420] 20 bytes
2019-02-16 13:19:13,458 - util.py[DEBUG]: Restoring selinux mode for /var/lib/cloud/instances/i-0d734ede44d97ba0b/sem/config_rightscale_userdata (recursive=False)
2019-02-16 13:19:13,459 - util.py[DEBUG]: Restoring selinux mode for /var/lib/cloud/instances/i-0d734ede44d97ba0b/sem/config_rightscale_userdata (recursive=False)
2019-02-16 13:19:13,459 - helpers.py[DEBUG]: Running config-rightscale_userdata using lock (<FileLock using file '/var/lib/cloud/instances/i-0d734ede44d97ba0b/sem/config_rightscale_userdata'>)
2019-02-16 13:19:13,459 - cc_rightscale_userdata.py[DEBUG]: Failed to get raw userdata in module rightscale_userdata
2019-02-16 13:19:13,460 - handlers.py[DEBUG]: finish: modules-final/config-rightscale_userdata: SUCCESS: config-rightscale_userdata ran successfully
2019-02-16 13:19:13,460 - stages.py[DEBUG]: Running module scripts-per-once (<module 'cloudinit.config.cc_scripts_per_once' from '/usr/lib/python2.7/site-packages/cloudinit/config/cc_scripts_per_once.pyc'>) with frequency once
2019-02-16 13:19:13,460 - handlers.py[DEBUG]: start: modules-final/config-scripts-per-once: running config-scripts-per-once with frequency once
2019-02-16 13:19:13,460 - util.py[DEBUG]: Writing to /var/lib/cloud/sem/config_scripts_per_once.once - wb: [420] 20 bytes
2019-02-16 13:19:13,460 - util.py[DEBUG]: Restoring selinux mode for /var/lib/cloud/sem/config_scripts_per_once.once (recursive=False)
2019-02-16 13:19:13,461 - util.py[DEBUG]: Restoring selinux mode for /var/lib/cloud/sem/config_scripts_per_once.once (recursive=False)
2019-02-16 13:19:13,461 - helpers.py[DEBUG]: Running config-scripts-per-once using lock (<FileLock using file '/var/lib/cloud/sem/config_scripts_per_once.once'>)
2019-02-16 13:19:13,461 - handlers.py[DEBUG]: finish: modules-final/config-scripts-per-once: SUCCESS: config-scripts-per-once ran successfully
2019-02-16 13:19:13,462 - stages.py[DEBUG]: Running module scripts-per-boot (<module 'cloudinit.config.cc_scripts_per_boot' from '/usr/lib/python2.7/site-packages/cloudinit/config/cc_scripts_per_boot.pyc'>) with frequency always
2019-02-16 13:19:13,462 - handlers.py[DEBUG]: start: modules-final/config-scripts-per-boot: running config-scripts-per-boot with frequency always
2019-02-16 13:19:13,462 - helpers.py[DEBUG]: Running config-scripts-per-boot using lock (<cloudinit.helpers.DummyLock object at 0x7fbb000df650>)
2019-02-16 13:19:13,462 - handlers.py[DEBUG]: finish: modules-final/config-scripts-per-boot: SUCCESS: config-scripts-per-boot ran successfully
2019-02-16 13:19:13,462 - stages.py[DEBUG]: Running module scripts-per-instance (<module 'cloudinit.config.cc_scripts_per_instance' from '/usr/lib/python2.7/site-packages/cloudinit/config/cc_scripts_per_instance.pyc'>) with frequency once-per-instance
2019-02-16 13:19:13,462 - handlers.py[DEBUG]: start: modules-final/config-scripts-per-instance: running config-scripts-per-instance with frequency once-per-instance
2019-02-16 13:19:13,462 - util.py[DEBUG]: Writing to /var/lib/cloud/instances/i-0d734ede44d97ba0b/sem/config_scripts_per_instance - wb: [420] 20 bytes
2019-02-16 13:19:13,463 - util.py[DEBUG]: Restoring selinux mode for /var/lib/cloud/instances/i-0d734ede44d97ba0b/sem/config_scripts_per_instance (recursive=False)
2019-02-16 13:19:13,463 - util.py[DEBUG]: Restoring selinux mode for /var/lib/cloud/instances/i-0d734ede44d97ba0b/sem/config_scripts_per_instance (recursive=False)
2019-02-16 13:19:13,464 - helpers.py[DEBUG]: Running config-scripts-per-instance using lock (<FileLock using file '/var/lib/cloud/instances/i-0d734ede44d97ba0b/sem/config_scripts_per_instance'>)
2019-02-16 13:19:13,464 - handlers.py[DEBUG]: finish: modules-final/config-scripts-per-instance: SUCCESS: config-scripts-per-instance ran successfully
2019-02-16 13:19:13,464 - stages.py[DEBUG]: Running module scripts-user (<module 'cloudinit.config.cc_scripts_user' from '/usr/lib/python2.7/site-packages/cloudinit/config/cc_scripts_user.pyc'>) with frequency once-per-instance
2019-02-16 13:19:13,464 - handlers.py[DEBUG]: start: modules-final/config-scripts-user: running config-scripts-user with frequency once-per-instance
2019-02-16 13:19:13,464 - util.py[DEBUG]: Writing to /var/lib/cloud/instances/i-0d734ede44d97ba0b/sem/config_scripts_user - wb: [420] 20 bytes
2019-02-16 13:19:13,465 - util.py[DEBUG]: Restoring selinux mode for /var/lib/cloud/instances/i-0d734ede44d97ba0b/sem/config_scripts_user (recursive=False)
2019-02-16 13:19:13,465 - util.py[DEBUG]: Restoring selinux mode for /var/lib/cloud/instances/i-0d734ede44d97ba0b/sem/config_scripts_user (recursive=False)
2019-02-16 13:19:13,466 - helpers.py[DEBUG]: Running config-scripts-user using lock (<FileLock using file '/var/lib/cloud/instances/i-0d734ede44d97ba0b/sem/config_scripts_user'>)
2019-02-16 13:19:13,466 - util.py[DEBUG]: Running command ['/var/lib/cloud/instance/scripts/part-001'] with allowed return codes [0] (shell=False, capture=False)
